Workbook

Sheet 1
A1: BẢNG LƯƠNG (từ 23.T8-1.T9/2026)
A2: STT | B2: HỌ TÊN | C2: GHI CHÚ | D2: CV | E2: 23 | F2: =E2+1 -> 24 | G2: =F2+1 -> 25 | H2: =G2+1 -> 26 | I2: =H2+1 -> 27 | J2: =I2+1 -> 28 | K2: 1 | L2: Đủ công | M2: Nửa công | N2: TC | O2: Lương/ngày | P2: Tổng lương | Q2: Ký nhận
E3: T2 | F3: T3 | G3: T4 | H3: T5 | I3: T6 | J3: T7 | K3: CN
A4: 1 | B4: A Lâm | C4: =SUBTOTAL(103,C5:C23) -> 15 | D4: ĐT | E4: x | F4: x | G4: x | H4: x | I4: x | J4: x | K4: x | L4: =COUNTIF(E4:K4,"X") -> 7 | M4: =COUNTIF(E4:I4,"X/2")/2 -> 0 | N4: =SUM(L4:M4) -> 7 | O4: 550000 | P4: =N4*O4 -> 3850000 | Q4: 500000
A5: 2 | B5: Nguyễn Tấn Tài | C5: Có CCCD gửi cty Hưng Long | D5: Thợ | I5: x | J5: x | K5: x | L5: =COUNTIF(E5:K5,"X") -> 3 | M5: =COUNTIF(E5:K5,"X/2")/2 -> 0 | N5: =SUM(L5:M5) -> 3 | O5: 380000 | P5: =N5*O5 -> 1140000
A6: =A5+1 -> 3 | B6: Nguyễn Tấn Hùng | D6: Thợ | L6: =COUNTIF(E6:K6,"X") -> 0 | M6: =COUNTIF(E6:K6,"X/2")/2 -> 0 | N6: =SUM(L6:M6) -> 0 | O6: 360000 | P6: =N6*O6 -> 0
A7: =A6+1 -> 4 | B7: Mai Văn Đời | C7: Có hình CCCD | D7: Thợ | I7: x | J7: x | K7: x | L7: =COUNTIF(E7:K7,"X") -> 3 | M7: =COUNTIF(E7:K7,"X/2")/2 -> 0 | N7: =SUM(L7:M7) -> 3 | O7: 370000 | P7: =N7*O7 -> 1110000
A8: =A7+1 -> 5 | B8: Nguyễn Văn Đấu | C8: Có CCCD gửi cty Hưng Long | D8: Thợ | E8: x/2 | F8: x | H8: x | I8: x | J8: x | L8: =COUNTIF(E8:K8,"X") -> 4 | M8: =COUNTIF(E8:K8,"X/2")/2 -> 0.5 | N8: =SUM(L8:M8) -> 4.5 | O8: 370000 | P8: =N8*O8 -> 1665000
A9: =A8+1 -> 6 | B9: Huỳnh Thanh Tùng | C9: Có hình CCCD | D9: Thợ ép | K9: x | L9: =COUNTIF(E9:K9,"X") -> 1 | M9: =COUNTIF(E9:K9,"X/2")/2 -> 0 | N9: =SUM(L9:M9) -> 1 | O9: 350000 | P9: =N9*O9 -> 350000
A10: =A9+1 -> 7 | B10: Nguyễn Hoàng Vũ | C10: Có CCCD gửi cty Hưng Long | D10: Phụ | G10: x | H10: x | I10: x | J10: x | L10: =COUNTIF(E10:K10,"X") -> 4 | M10: =COUNTIF(E10:K10,"X/2")/2 -> 0 | N10: =SUM(L10:M10) -> 4 | O10: 320000 | P10: =N10*O10 -> 1280000
A11: =A10+1 -> 8 | B11: Nguyễn Văn Phong | C11: Có hình CCCD | D11: Phụ | L11: =COUNTIF(E11:K11,"X") -> 0 | M11: =COUNTIF(E11:K11,"X/2")/2 -> 0 | N11: =SUM(L11:M11) -> 0 | O11: 300000 | P11: =N11*O11 -> 0
A12: =A11+1 -> 9 | B12: Nguyễn Công Thức | C12: Có CCCD gửi cty Hưng Long | D12: Phụ | E12: x | F12: x | G12: x | H12: x | I12: x | J12: x | K12: x | L12: =COUNTIF(E12:K12,"X") -> 7 | M12: =COUNTIF(E12:K12,"X/2")/2 -> 0 | N12: =SUM(L12:M12) -> 7 | O12: 360000 | P12: =N12*O12 -> 2520000
A13: =A12+1 -> 10 | B13: Nguyễn Tấn Lợi | C13: Có hình CCCD | D13: Thợ | F13: x | G13: x | H13: x | J13: x | K13: x | L13: =COUNTIF(E13:K13,"X") -> 5 | M13: =COUNTIF(E13:K13,"X/2")/2 -> 0 | N13: =SUM(L13:M13) -> 5 | O13: 400000 | P13: =N13*O13 -> 2000000
A14: 11 | B14: Mai Văn Bảy | C14: Có hình CCCD | D14: Phụ | F14: x | G14: x | H14: x | I14: x | J14: x | L14: =COUNTIF(E14:K14,"X") -> 5 | M14: =COUNTIF(E14:K14,"X/2")/2 -> 0 | N14: =SUM(L14:M14) -> 5 | O14: 280000 | P14: =N14*O14 -> 1400000
A15: =A14+1 -> 12 | B15: Huỳnh Chí Linh | C15: Có hình CCCD | D15: Thợ | J15: x/2 | K15: x | L15: =COUNTIF(E15:K15,"X") -> 1 | M15: =COUNTIF(E15:K15,"X/2")/2 -> 0.5 | N15: =SUM(L15:M15) -> 1.5 | O15: 400000 | P15: =N15*O15 -> 600000
A16: =A15+1 -> 13 | B16: Nguyễn Văn Yêm | D16: Thợ | G16: x | H16: x | I16: x | J16: x | L16: =COUNTIF(E16:K16,"X") -> 4 | M16: =COUNTIF(E16:K16,"X/2")/2 -> 0 | N16: =SUM(L16:M16) -> 4 | O16: 390000 | P16: =N16*O16 -> 1560000
A17: 14 | B17: Nguyễn Thanh Tùng | C17: Có CCCD gửi cty Hưng Long | D17: Thợ | F17: x | G17: x | H17: x | I17: x | J17: x | K17: x | L17: =COUNTIF(E17:K17,"X") -> 6 | M17: =COUNTIF(E17:K17,"X/2")/2 -> 0 | N17: =SUM(L17:M17) -> 6 | O17: 370000 | P17: =N17*O17 -> 2220000
A18: 15 | B18: Nguyễn Văn Mười | D18: Thợ | L18: =COUNTIF(E18:K18,"X") -> 0 | M18: =COUNTIF(E18:K18,"X/2")/2 -> 0 | N18: =SUM(L18:M18) -> 0 | O18: 360000 | P18: =N18*O18 -> 0
A19: 16 | B19: Phạm Văn Kiệt | C19: Có CCCD gửi cty Hưng Long | D19: Thợ | I19: x | J19: x | L19: =COUNTIF(E19:K19,"X") -> 2 | M19: =COUNTIF(E19:K19,"X/2")/2 -> 0 | N19: =SUM(L19:M19) -> 2 | O19: 380000 | P19: =N19*O19 -> 760000
A20: 17 | B20: Trương Văn Thông | C20: Có CCCD gửi cty Hưng Long | D20: Phụ | L20: =COUNTIF(E20:K20,"X") -> 0 | M20: =COUNTIF(E20:K20,"X/2")/2 -> 0 | N20: =SUM(L20:M20) -> 0 | O20: 270000 | P20: =N20*O20 -> 0
A21: 18 | B21: Võ Hoàng Nam | C21: Có CCCD gửi cty Hưng Long | D21: Thợ | E21: x/2 | F21: x | G21: x | H21: x | J21: x | L21: =COUNTIF(E21:K21,"X") -> 4 | M21: =COUNTIF(E21:K21,"X/2")/2 -> 0.5 | N21: =SUM(L21:M21) -> 4.5 | O21: 380000 | P21: =N21*O21 -> 1710000
A22: 19 | B22: Trần Thanh Sơn | C22: Có CCCD gửi cty Hưng Long | D22: Thợ | L22: =COUNTIF(E22:K22,"X") -> 0 | M22: =COUNTIF(E22:K22,"X/2")/2 -> 0 | N22: =SUM(L22:M22) -> 0 | O22: 370000 | P22: =N22*O22 -> 0
A23: 20 | B23: Đinh Văn Thống | D23: Phụ | L23: =COUNTIF(E23:K23,"X") -> 0 | M23: =COUNTIF(E23:K23,"X/2")/2 -> 0 | N23: =SUM(L23:M23) -> 0 | O23: 280000 | P23: =N23*O23 -> 0
A24: 21 | B24: Lê Vũ Linh | D24: Thợ | F24: x | G24: x | H24: x | I24: x | J24: x | K24: x | L24: =COUNTIF(E24:K24,"X") -> 6 | M24: =COUNTIF(E24:K24,"X/2")/2 -> 0 | N24: =SUM(L24:M24) -> 6 | O24: 380000 | P24: =N24*O24 -> 2280000
A25: 22 | B25: Nguyễn Thị Cười | D25: Thợ | G25: x | H25: x | I25: x | J25: x | K25: x | L25: =COUNTIF(E25:K25,"X") -> 5 | M25: =COUNTIF(E25:K25,"X/2")/2 -> 0 | N25: =SUM(L25:M25) -> 5 | O25: 280000 | P25: =N25*O25 -> 1400000
A26: 23 | B26: Huỳnh Thanh Xuân | D26: Phụ | L26: =COUNTIF(E26:K26,"X") -> 0 | M26: =COUNTIF(E26:K26,"X/2")/2 -> 0 | N26: =SUM(L26:M26) -> 0 | O26: 270000 | P26: =N26*O26 -> 0
A27: 24 | B27: Lâm Hữu Phước | D27: Phụ | G27: x | H27: x | I27: x | J27: x | L27: =COUNTIF(E27:K27,"X") -> 4 | M27: =COUNTIF(E27:K27,"X/2")/2 -> 0 | N27: =SUM(L27:M27) -> 4 | O27: 280000 | P27: =N27*O27 -> 1120000
A28: 25 | B28: Nguyễn Văn Phao | D28: Thợ | L28: =COUNTIF(E28:K28,"X") -> 0 | M28: =COUNTIF(E28:K28,"X/2")/2 -> 0 | N28: =SUM(L28:M28) -> 0 | O28: 370000 | P28: =N28*O28 -> 0
A29: 26 | B29: Nguyễn Văn Đa | D29: Phụ | L29: =COUNTIF(E29:K29,"X") -> 0 | M29: =COUNTIF(E29:K29,"X/2")/2 -> 0 | N29: =SUM(L29:M29) -> 0 | O29: 260000 | P29: =N29*O29 -> 0
A30: 27 | B30: Lâm Kỳ Phi | D30: Thợ | F30: x | G30: x | H30: x | I30: x | J30: x | K30: x | L30: =COUNTIF(E30:K30,"X") -> 6 | M30: =COUNTIF(E30:K30,"X/2")/2 -> 0 | N30: =SUM(L30:M30) -> 6 | O30: 380000 | P30: =N30*O30 -> 2280000
A31: 28 | B31: Trần Thanh Phong | D31: Thợ | G31: x | H31: x | I31: x | J31: x | L31: =COUNTIF(E31:K31,"X") -> 4 | M31: =COUNTIF(E31:K31,"X/2")/2 -> 0 | N31: =SUM(L31:M31) -> 4 | O31: 370000 | P31: =N31*O31 -> 1480000
A32: 29 | B32: Trịnh Văn Phước | D32: Thợ | H32: x | J32: x | L32: =COUNTIF(E32:K32,"X") -> 2 | M32: =COUNTIF(E32:K32,"X/2")/2 -> 0 | N32: =SUM(L32:M32) -> 2 | O32: 370000 | P32: =N32*O32 -> 740000
A33: 30 | B33: Nguyễn Văn Liễu | D33: Thợ | E33: x/2 | F33: x | G33: x | H33: x | J33: x | K33: x | L33: =COUNTIF(E33:K33,"X") -> 5 | M33: =COUNTIF(E33:K33,"X/2")/2 -> 0.5 | N33: =SUM(L33:M33) -> 5.5 | O33: 360000 | P33: =N33*O33 -> 1980000
A34: 31 | B34: Nguyễn Quốc Thiện | D34: Phụ | E34: x | F34: x | G34: x | H34: x | J34: x | K34: x | L34: =COUNTIF(E34:K34,"X") -> 6 | M34: =COUNTIF(E34:K34,"X/2")/2 -> 0 | N34: =SUM(L34:M34) -> 6 | O34: 280000 | P34: =N34*O34 -> 1680000
A35: 32 | B35: Nguyễn Văn Cường | D35: Thợ | G35: x | H35: x | J35: x | L35: =COUNTIF(E35:K35,"X") -> 3 | M35: =COUNTIF(E35:K35,"X/2")/2 -> 0 | N35: =SUM(L35:M35) -> 3 | O35: 370000 | P35: =N35*O35 -> 1110000
A36: 33 | B36: Nguyễn Thu Mè | D36: Phụ | G36: x | H36: x | J36: x | L36: =COUNTIF(E36:K36,"X") -> 3 | M36: =COUNTIF(E36:K36,"X/2")/2 -> 0 | N36: =SUM(L36:M36) -> 3 | O36: 270000 | P36: =N36*O36 -> 810000
A37: 34 | B37: Nguyễn Văn Chờ | D37: Thợ | E37: x/2 | F37: x | G37: x | H37: x | I37: x | J37: x | K37: x | L37: =COUNTIF(E37:K37,"X") -> 6 | M37: =COUNTIF(E37:K37,"X/2")/2 -> 0.5 | N37: =SUM(L37:M37) -> 6.5 | O37: 360000 | P37: =N37*O37 -> 2340000
A38: 35 | B38: Nguyễn Văn Châu | D38: Phụ | G38: x | H38: x | I38: x | J38: x | K38: x | L38: =COUNTIF(E38:K38,"X") -> 5 | M38: =COUNTIF(E38:K38,"X/2")/2 -> 0 | N38: =SUM(L38:M38) -> 5 | O38: 270000 | P38: =N38*O38 -> 1350000
A39: 36 | B39: Lê Quốc Thịnh | D39: Phụ | L39: =COUNTIF(E39:K39,"X") -> 0 | M39: =COUNTIF(E39:K39,"X/2")/2 -> 0 | N39: =SUM(L39:M39) -> 0 | O39: 260000 | P39: =N39*O39 -> 0
A40: 37 | B40: Lê Văn Xết | D40: Thợ | L40: =COUNTIF(E40:K40,"X") -> 0 | M40: =COUNTIF(E40:K40,"X/2")/2 -> 0 | N40: =SUM(L40:M40) -> 0 | O40: 360000 | P40: =N40*O40 -> 0
...

Sheet 2
A1: BẢNG LƯƠNG (từ 2-10.T9/2026)
A2: STT | B2: HỌ TÊN | C2: GHI CHÚ | D2: CV | E2: 2 | F2: =E2+1 -> 3 | G2: =F2+1 -> 4 | H2: =G2+1 -> 5 | I2: =H2+1 -> 6 | J2: =I2+1 -> 7 | K2: =J2+1 -> 8 | L2: =K2+1 -> 9 | M2: =L2+1 -> 10 | N2: Đủ công | O2: Nửa công | P2: TC | Q2: Lương/ngày | R2: Tổng lương | S2: Ký nhận
E3: T2 | F3: T3 | G3: T4 | H3: T5 | I3: T6 | J3: T7 | K3: CN | L3: T2 | M3: T3
A4: 1 | B4: A Lâm | C4: =SUBTOTAL(103,C5:C23) -> 15 | D4: ĐT | E4: x | F4: x | G4: x | H4: x | I4: x | J4: x | K4: x | L4: x | M4: x | N4: =COUNTIF(E4:M4,"X") -> 9 | O4: =COUNTIF(E4:I4,"X/2")/2 -> 0 | P4: =SUM(N4:O4) -> 9 | Q4: 550000 | R4: =P4*Q4 -> 4950000 | S4: 9600000
A5: 2 | B5: Nguyễn Tấn Tài | C5: Có CCCD gửi cty Hưng Long | D5: Thợ | E5: x | F5: x | G5: x | H5: x | I5: x | J5: x | K5: x | L5: x | M5: x | N5: =COUNTIF(E5:M5,"X") -> 9 | O5: =COUNTIF(E5:M5,"X/2")/2 -> 0 | P5: =SUM(N5:O5) -> 9 | Q5: 380000 | R5: =P5*Q5 -> 3420000
A6: =A5+1 -> 3 | B6: Nguyễn Tấn Hùng | D6: Thợ | N6: =COUNTIF(E6:M6,"X") -> 0 | O6: =COUNTIF(E6:M6,"X/2")/2 -> 0 | P6: =SUM(N6:O6) -> 0 | Q6: 360000 | R6: =P6*Q6 -> 0
A7: =A6+1 -> 4 | B7: Mai Văn Đời | C7: Có hình CCCD | D7: Thợ | E7: x | F7: x | G7: x | H7: x | J7: x | K7: x | L7: x | M7: x | N7: =COUNTIF(E7:M7,"X") -> 8 | O7: =COUNTIF(E7:M7,"X/2")/2 -> 0 | P7: =SUM(N7:O7) -> 8 | Q7: 370000 | R7: =P7*Q7 -> 2960000
A8: =A7+1 -> 5 | B8: Nguyễn Văn Đấu | C8: Có CCCD gửi cty Hưng Long | D8: Thợ | E8: x | F8: x | G8: x | I8: x | J8: x | L8: x | M8: x | N8: =COUNTIF(E8:M8,"X") -> 7 | O8: =COUNTIF(E8:M8,"X/2")/2 -> 0 | P8: =SUM(N8:O8) -> 7 | Q8: 370000 | R8: =P8*Q8 -> 2590000 | S8: 1100000
A9: =A8+1 -> 6 | B9: Huỳnh Thanh Tùng | C9: Có hình CCCD | D9: Thợ ép | E9: x | G9: x | H9: x | I9: x | J9: x | K9: x | L9: x | N9: =COUNTIF(E9:M9,"X") -> 7 | O9: =COUNTIF(E9:M9,"X/2")/2 -> 0 | P9: =SUM(N9:O9) -> 7 | Q9: 350000 | R9: =P9*Q9 -> 2450000
A10: =A9+1 -> 7 | B10: Nguyễn Hoàng Vũ | C10: Có CCCD gửi cty Hưng Long | D10: Phụ | E10: x | F10: x | G10: x | H10: x | I10: x | J10: x | K10: x | M10: x | N10: =COUNTIF(E10:M10,"X") -> 8 | O10: =COUNTIF(E10:M10,"X/2")/2 -> 0 | P10: =SUM(N10:O10) -> 8 | Q10: 320000 | R10: =P10*Q10 -> 2560000
A11: =A10+1 -> 8 | B11: Nguyễn Văn Phong | C11: Có hình CCCD | D11: Phụ | E11: x | F11: x | G11: x | H11: x | I11: x | J11: x | K11: x | L11: x | M11: x | N11: =COUNTIF(E11:M11,"X") -> 9 | O11: =COUNTIF(E11:M11,"X/2")/2 -> 0 | P11: =SUM(N11:O11) -> 9 | Q11: 300000 | R11: =P11*Q11 -> 2700000
A12: =A11+1 -> 9 | B12: Nguyễn Công Thức | C12: Có CCCD gửi cty Hưng Long | D12: Phụ | E12: x | F12: x | G12: x | H12: x | I12: x | J12: x | K12: x | L12: x | M12: x | N12: =COUNTIF(E12:M12,"X") -> 9 | O12: =COUNTIF(E12:M12,"X/2")/2 -> 0 | P12: =SUM(N12:O12) -> 9 | Q12: 360000 | R12: =P12*Q12 -> 3240000
A13: =A12+1 -> 10 | B13: Nguyễn Tấn Lợi | C13: Có hình CCCD | D13: Thợ | E13: x | F13: x | G13: x | H13: x | I13: x | J13: x | K13: x | L13: x | M13: x | N13: =COUNTIF(E13:M13,"X") -> 9 | O13: =COUNTIF(E13:M13,"X/2")/2 -> 0 | P13: =SUM(N13:O13) -> 9 | Q13: 400000 | R13: =P13*Q13 -> 3600000
A14: 11 | B14: Mai Văn Bảy | C14: Có hình CCCD | D14: Phụ | E14: x | F14: x | G14: x | H14: x | I14: x | J14: x | L14: x | M14: x | N14: =COUNTIF(E14:M14,"X") -> 8 | O14: =COUNTIF(E14:M14,"X/2")/2 -> 0 | P14: =SUM(N14:O14) -> 8 | Q14: 280000 | R14: =P14*Q14 -> 2240000
A15: =A14+1 -> 12 | B15: Huỳnh Chí Linh | C15: Có hình CCCD | D15: Thợ | E15: x | F15: x | G15: x | H15: x | I15: x | J15: x/2 | L15: x | M15: x/2 | N15: =COUNTIF(E15:M15,"X") -> 6 | O15: =COUNTIF(E15:M15,"X/2")/2 -> 1 | P15: =SUM(N15:O15) -> 7 | Q15: 400000 | R15: =P15*Q15 -> 2800000
A16: =A15+1 -> 13 | B16: Nguyễn Văn Yêm | D16: Thợ | E16: x | F16: x | G16: x | H16: x | I16: x | K16: x | L16: x | M16: x | N16: =COUNTIF(E16:M16,"X") -> 8 | O16: =COUNTIF(E16:M16,"X/2")/2 -> 0 | P16: =SUM(N16:O16) -> 8 | Q16: 390000 | R16: =P16*Q16 -> 3120000
A17: 14 | B17: Nguyễn Thanh Tùng | C17: Có CCCD gửi cty Hưng Long | D17: Thợ | E17: x | F17: x | G17: x | H17: x | I17: x | J17: x | L17: x | M17: x | N17: =COUNTIF(E17:M17,"X") -> 8 | O17: =COUNTIF(E17:M17,"X/2")/2 -> 0 | P17: =SUM(N17:O17) -> 8 | Q17: 370000 | R17: =P17*Q17 -> 2960000
A18: 15 | B18: Nguyễn Văn Mười | D18: Thợ | M18: x | N18: =COUNTIF(E18:M18,"X") -> 1 | O18: =COUNTIF(E18:M18,"X/2")/2 -> 0 | P18: =SUM(N18:O18) -> 1 | Q18: 360000 | R18: =P18*Q18 -> 360000
A19: 16 | B19: Phạm Văn Kiệt | C19: Có CCCD gửi cty Hưng Long | D19: Thợ | E19: x | F19: x | G19: x | H19: x | I19: x | J19: x | K19: x | L19: x | M19: x | N19: =COUNTIF(E19:M19,"X") -> 9 | O19: =COUNTIF(E19:M19,"X/2")/2 -> 0 | P19: =SUM(N19:O19) -> 9 | Q19: 380000 | R19: =P19*Q19 -> 3420000
A20: 17 | B20: Trương Văn Thông | C20: Có CCCD gửi cty Hưng Long | D20: Phụ | E20: x | F20: x | G20: x | H20: x | I20: x | J20: x | L20: x | M20: x | N20: =COUNTIF(E20:M20,"X") -> 8 | O20: =COUNTIF(E20:M20,"X/2")/2 -> 0 | P20: =SUM(N20:O20) -> 8 | Q20: 270000 | R20: =P20*Q20 -> 2160000
A21: 18 | B21: Võ Hoàng Nam | C21: Có CCCD gửi cty Hưng Long | D21: Thợ | E21: x | F21: x | G21: x | H21: x | J21: x | L21: x | M21: x | N21: =COUNTIF(E21:M21,"X") -> 7 | O21: =COUNTIF(E21:M21,"X/2")/2 -> 0 | P21: =SUM(N21:O21) -> 7 | Q21: 380000 | R21: =P21*Q21 -> 2660000
A22: 19 | B22: Trần Thanh Sơn | C22: Có CCCD gửi cty Hưng Long | D22: Thợ | I22: x | J22: x | N22: =COUNTIF(E22:M22,"X") -> 2 | O22: =COUNTIF(E22:M22,"X/2")/2 -> 0 | P22: =SUM(N22:O22) -> 2 | Q22: 370000 | R22: =P22*Q22 -> 740000
A23: 20 | B23: Đinh Văn Thống | D23: Phụ | N23: =COUNTIF(E23:M23,"X") -> 0 | O23: =COUNTIF(E23:M23,"X/2")/2 -> 0 | P23: =SUM(N23:O23) -> 0 | Q23: 280000 | R23: =P23*Q23 -> 0
A24: 21 | B24: Lê Vũ Linh | D24: Thợ | E24: x | F24: x | G24: x | H24: x | J24: x | K24: x | L24: x | M24: x | N24: =COUNTIF(E24:M24,"X") -> 8 | O24: =COUNTIF(E24:M24,"X/2")/2 -> 0 | P24: =SUM(N24:O24) -> 8 | Q24: 380000 | R24: =P24*Q24 -> 3040000
A25: 22 | B25: Nguyễn Thị Cười | D25: Thợ | E25: x | F25: x | G25: x | H25: x | J25: x | K25: x | L25: x | N25: =COUNTIF(E25:M25,"X") -> 7 | O25: =COUNTIF(E25:M25,"X/2")/2 -> 0 | P25: =SUM(N25:O25) -> 7 | Q25: 280000 | R25: =P25*Q25 -> 1960000
A26: 23 | B26: Huỳnh Thanh Xuân | D26: Phụ | N26: =COUNTIF(E26:M26,"X") -> 0 | O26: =COUNTIF(E26:M26,"X/2")/2 -> 0 | P26: =SUM(N26:O26) -> 0 | Q26: 270000 | R26: =P26*Q26 -> 0
A27: 24 | B27: Lâm Hữu Phước | D27: Phụ | E27: x | F27: x | G27: x | H27: x | I27: x | J27: x | N27: =COUNTIF(E27:M27,"X") -> 6 | O27: =COUNTIF(E27:M27,"X/2")/2 -> 0 | P27: =SUM(N27:O27) -> 6 | Q27: 280000 | R27: =P27*Q27 -> 1680000
A28: 25 | B28: Nguyễn Văn Phao | D28: Thợ | N28: =COUNTIF(E28:M28,"X") -> 0 | O28: =COUNTIF(E28:M28,"X/2")/2 -> 0 | P28: =SUM(N28:O28) -> 0 | Q28: 370000 | R28: =P28*Q28 -> 0
A29: 26 | B29: Nguyễn Văn Đa | D29: Phụ | N29: =COUNTIF(E29:M29,"X") -> 0 | O29: =COUNTIF(E29:M29,"X/2")/2 -> 0 | P29: =SUM(N29:O29) -> 0 | Q29: 260000 | R29: =P29*Q29 -> 0
A30: 27 | B30: Lâm Kỳ Phi | D30: Thợ | E30: x | F30: x | G30: x | H30: x | I30: x | J30: x | K30: x | N30: =COUNTIF(E30:M30,"X") -> 7 | O30: =COUNTIF(E30:M30,"X/2")/2 -> 0 | P30: =SUM(N30:O30) -> 7 | Q30: 380000 | R30: =P30*Q30 -> 2660000
A31: 28 | B31: Trần Thanh Phong | D31: Thợ | E31: x | F31: x | G31: x | H31: x | I31: x | J31: x | L31: x | M31: x | N31: =COUNTIF(E31:M31,"X") -> 8 | O31: =COUNTIF(E31:M31,"X/2")/2 -> 0 | P31: =SUM(N31:O31) -> 8 | Q31: 370000 | R31: =P31*Q31 -> 2960000
A32: 29 | B32: Trịnh Văn Phước | D32: Thợ | E32: x | F32: x | G32: x | H32: x | I32: x | N32: =COUNTIF(E32:M32,"X") -> 5 | O32: =COUNTIF(E32:M32,"X/2")/2 -> 0 | P32: =SUM(N32:O32) -> 5 | Q32: 380000 | R32: =P32*Q32 -> 1900000
A33: 30 | B33: Nguyễn Văn Liễu | D33: Thợ | E33: x | F33: x | G33: x | H33: x | I33: x | J33: x | L33: x | N33: =COUNTIF(E33:M33,"X") -> 7 | O33: =COUNTIF(E33:M33,"X/2")/2 -> 0 | P33: =SUM(N33:O33) -> 7 | Q33: 360000 | R33: =P33*Q33 -> 2520000
A34: 31 | B34: Nguyễn Quốc Thiện | D34: Phụ | E34: x | F34: x | G34: x | H34: x | I34: x | J34: x | K34: x | N34: =COUNTIF(E34:M34,"X") -> 7 | O34: =COUNTIF(E34:M34,"X/2")/2 -> 0 | P34: =SUM(N34:O34) -> 7 | Q34: 280000 | R34: =P34*Q34 -> 1960000
A35: 32 | B35: Nguyễn Văn Cường | D35: Thợ | E35: x | F35: x | G35: x | H35: x | I35: x | J35: x | L35: x | M35: x | N35: =COUNTIF(E35:M35,"X") -> 8 | O35: =COUNTIF(E35:M35,"X/2")/2 -> 0 | P35: =SUM(N35:O35) -> 8 | Q35: 370000 | R35: =P35*Q35 -> 2960000
A36: 33 | B36: Nguyễn Thu Mè | D36: Phụ | E36: x | F36: x | G36: x | H36: x | I36: x | J36: x | L36: x | M36: x | N36: =COUNTIF(E36:M36,"X") -> 8 | O36: =COUNTIF(E36:M36,"X/2")/2 -> 0 | P36: =SUM(N36:O36) -> 8 | Q36: 270000 | R36: =P36*Q36 -> 2160000
A37: 34 | B37: Nguyễn Văn Chờ | D37: Thợ | E37: x | F37: x | G37: x | H37: x | I37: x | J37: x | L37: x | N37: =COUNTIF(E37:M37,"X") -> 7 | O37: =COUNTIF(E37:M37,"X/2")/2 -> 0 | P37: =SUM(N37:O37) -> 7 | Q37: 360000 | R37: =P37*Q37 -> 2520000
A38: 35 | B38: Nguyễn Văn Châu | D38: Phụ | E38: x | F38: x | G38: x | H38: x | I38: x | J38: x | L38: x | M38: x | N38: =COUNTIF(E38:M38,"X") -> 8 | O38: =COUNTIF(E38:M38,"X/2")/2 -> 0 | P38: =SUM(N38:O38) -> 8 | Q38: 270000 | R38: =P38*Q38 -> 2160000
A39: 36 | B39: Lê Quốc Thịnh | D39: Phụ | N39: =COUNTIF(E39:M39,"X") -> 0 | O39: =COUNTIF(E39:M39,"X/2")/2 -> 0 | P39: =SUM(N39:O39) -> 0 | Q39: 260000 | R39: =P39*Q39 -> 0
A40: 37 | B40: Lê Văn Xết | D40: Thợ | N40: =COUNTIF(E40:M40,"X") -> 0 | O40: =COUNTIF(E40:M40,"X/2")/2 -> 0 | P40: =SUM(N40:O40) -> 0 | Q40: 360000 | R40: =P40*Q40 -> 0
...

Sheet 3
A1: BẢNG LƯƠNG (từ 11-20.T3/2026)
A2: STT | B2: HỌ TÊN | C2: GHI CHÚ | D2: CV | E2: 11 | F2: =E2+1 -> 12 | G2: =F2+1 -> 13 | H2: =G2+1 -> 14 | I2: =H2+1 -> 15 | J2: =I2+1 -> 16 | K2: =J2+1 -> 17 | L2: =K2+1 -> 18 | M2: 19 | N2: 20 | O2: Đủ công | P2: Nửa công | Q2: TC | R2: Lương/ngày | S2: Tổng lương | T2: Ký nhận
E3: T4 | F3: T5 | G3: T6 | H3: T7 | I3: CN | J3: T2 | K3: CN | L3: T3 | M3: T4 | N3: T5
A4: 1 | B4: A Lâm | C4: =SUBTOTAL(103,C5:C23) -> 15 | D4: ĐT | E4: x | F4: x | G4: x | H4: x | I4: x | J4: x | K4: x | L4: x | M4: x | N4: x | O4: =COUNTIF(E4:N4,"X") -> 10 | P4: =COUNTIF(E4:I4,"X/2")/2 -> 0 | Q4: =SUM(O4:P4) -> 10 | R4: 550000 | S4: =Q4*R4 -> 5500000
A5: 2 | B5: Nguyễn Tấn Tài | C5: Có CCCD gửi cty Hưng Long | D5: Thợ | E5: x | F5: x | G5: x | H5: x | J5: x | K5: x | L5: x | M5: x | N5: x | O5: =COUNTIF(E5:N5,"X") -> 9 | P5: =COUNTIF(E5:N5,"X/2")/2 -> 0 | Q5: =SUM(O5:P5) -> 9 | R5: 380000 | S5: =Q5*R5 -> 3420000
A6: =A5+1 -> 3 | B6: Nguyễn Tấn Hùng | D6: Thợ | O6: =COUNTIF(E6:N6,"X") -> 0 | P6: =COUNTIF(E6:N6,"X/2")/2 -> 0 | Q6: =SUM(O6:P6) -> 0 | R6: 360000 | S6: =Q6*R6 -> 0
A7: =A6+1 -> 4 | B7: Mai Văn Đời | C7: Có hình CCCD | D7: Thợ | E7: x | F7: x | G7: x | H7: x | J7: x | K7: x | L7: x | M7: x | N7: x | O7: =COUNTIF(E7:N7,"X") -> 9 | P7: =COUNTIF(E7:N7,"X/2")/2 -> 0 | Q7: =SUM(O7:P7) -> 9 | R7: 370000 | S7: =Q7*R7 -> 3330000
A8: =A7+1 -> 5 | B8: Nguyễn Văn Đấu | C8: Có CCCD gửi cty Hưng Long | D8: Thợ | E8: x | F8: x | G8: x | H8: x | J8: x | L8: x | M8: x | N8: x | O8: =COUNTIF(E8:N8,"X") -> 8 | P8: =COUNTIF(E8:N8,"X/2")/2 -> 0 | Q8: =SUM(O8:P8) -> 8 | R8: 370000 | S8: =Q8*R8 -> 2960000 | T8: 300000
A9: =A8+1 -> 6 | B9: Huỳnh Thanh Tùng | C9: Có hình CCCD | D9: Thợ ép | E9: x | G9: x | I9: x | J9: x | K9: x | O9: =COUNTIF(E9:N9,"X") -> 5 | P9: =COUNTIF(E9:N9,"X/2")/2 -> 0 | Q9: =SUM(O9:P9) -> 5 | R9: 350000 | S9: =Q9*R9 -> 1750000
A10: =A9+1 -> 7 | B10: Nguyễn Hoàng Vũ | C10: Có CCCD gửi cty Hưng Long | D10: Phụ | E10: x | F10: x | G10: x | H10: x | J10: x | K10: x | L10: x | M10: x | N10: x | O10: =COUNTIF(E10:N10,"X") -> 9 | P10: =COUNTIF(E10:N10,"X/2")/2 -> 0 | Q10: =SUM(O10:P10) -> 9 | R10: 320000 | S10: =Q10*R10 -> 2880000
A11: =A10+1 -> 8 | B11: Nguyễn Văn Phong | C11: Có hình CCCD | D11: Phụ | E11: x | F11: x | G11: x | H11: x | I11: x | J11: x | K11: x | L11: x | M11: x | N11: x | O11: =COUNTIF(E11:N11,"X") -> 10 | P11: =COUNTIF(E11:N11,"X/2")/2 -> 0 | Q11: =SUM(O11:P11) -> 10 | R11: 300000 | S11: =Q11*R11 -> 3000000 | T11: -150000
A12: =A11+1 -> 9 | B12: Nguyễn Công Thức | C12: Có CCCD gửi cty Hưng Long | D12: Phụ | E12: x | F12: x | G12: x | H12: x | I12: x | J12: x | K12: x | L12: x | M12: x | N12: x | O12: =COUNTIF(E12:N12,"X") -> 10 | P12: =COUNTIF(E12:N12,"X/2")/2 -> 0 | Q12: =SUM(O12:P12) -> 10 | R12: 360000 | S12: =Q12*R12 -> 3600000
A13: =A12+1 -> 10 | B13: Nguyễn Tấn Lợi | C13: Có hình CCCD | D13: Thợ | E13: x | F13: x | G13: x | H13: x | J13: x | K13: x | L13: x | M13: x | O13: =COUNTIF(E13:N13,"X") -> 8 | P13: =COUNTIF(E13:N13,"X/2")/2 -> 0 | Q13: =SUM(O13:P13) -> 8 | R13: 400000 | S13: =Q13*R13 -> 3200000
A14: 11 | B14: Mai Văn Bảy | C14: Có hình CCCD | D14: Phụ | E14: x | F14: x | G14: x | H14: x | J14: x | K14: x | L14: x | M14: x | N14: x | O14: =COUNTIF(E14:N14,"X") -> 9 | P14: =COUNTIF(E14:N14,"X/2")/2 -> 0 | Q14: =SUM(O14:P14) -> 9 | R14: 280000 | S14: =Q14*R14 -> 2520000
A15: =A14+1 -> 12 | B15: Huỳnh Chí Linh | C15: Có hình CCCD | D15: Thợ | N15: x | O15: =COUNTIF(E15:N15,"X") -> 1 | P15: =COUNTIF(E15:N15,"X/2")/2 -> 0 | Q15: =SUM(O15:P15) -> 1 | R15: 400000 | S15: =Q15*R15 -> 400000
A16: =A15+1 -> 13 | B16: Nguyễn Văn Yêm | D16: Thợ | E16: x | F16: x | G16: x | H16: x | J16: x | K16: x | L16: x | M16: x | N16: x | O16: =COUNTIF(E16:N16,"X") -> 9 | P16: =COUNTIF(E16:N16,"X/2")/2 -> 0 | Q16: =SUM(O16:P16) -> 9 | R16: 390000 | S16: =Q16*R16 -> 3510000
A17: 14 | B17: Nguyễn Thanh Tùng | C17: Có CCCD gửi cty Hưng Long | D17: Thợ | E17: x | F17: x | G17: x | H17: x | J17: x | K17: x | L17: x | O17: =COUNTIF(E17:N17,"X") -> 7 | P17: =COUNTIF(E17:N17,"X/2")/2 -> 0 | Q17: =SUM(O17:P17) -> 7 | R17: 370000 | S17: =Q17*R17 -> 2590000
A18: 15 | B18: Nguyễn Văn Mười | D18: Thợ | E18: x | F18: x | G18: x | H18: x | I18: x | J18: x | K18: x | L18: x | M18: x | O18: =COUNTIF(E18:N18,"X") -> 9 | P18: =COUNTIF(E18:N18,"X/2")/2 -> 0 | Q18: =SUM(O18:P18) -> 9 | R18: 360000 | S18: =Q18*R18 -> 3240000
A19: 16 | B19: Phạm Văn Kiệt | C19: Có CCCD gửi cty Hưng Long | D19: Thợ | E19: x | F19: x | G19: x | H19: x | I19: x/2 | L19: x | M19: x | O19: =COUNTIF(E19:N19,"X") -> 6 | P19: =COUNTIF(E19:N19,"X/2")/2 -> 0.5 | Q19: =SUM(O19:P19) -> 6.5 | R19: 380000 | S19: =Q19*R19 -> 2470000
A20: 17 | B20: Trương Văn Thông | C20: Có CCCD gửi cty Hưng Long | D20: Phụ | E20: x | F20: x | G20: x | H20: x | I20: x | K20: x | L20: x | M20: x | N20: x | O20: =COUNTIF(E20:N20,"X") -> 9 | P20: =COUNTIF(E20:N20,"X/2")/2 -> 0 | Q20: =SUM(O20:P20) -> 9 | R20: 270000 | S20: =Q20*R20 -> 2430000
A21: 18 | B21: Võ Hoàng Nam | C21: Có CCCD gửi cty Hưng Long | D21: Thợ | E21: x | H21: x | J21: x | K21: x | L21: x | M21: x | N21: x | O21: =COUNTIF(E21:N21,"X") -> 7 | P21: =COUNTIF(E21:N21,"X/2")/2 -> 0 | Q21: =SUM(O21:P21) -> 7 | R21: 380000 | S21: =Q21*R21 -> 2660000
A22: 19 | B22: Trần Thanh Sơn | C22: Có CCCD gửi cty Hưng Long | D22: Thợ | H22: x | J22: x | K22: x | L22: x | O22: =COUNTIF(E22:N22,"X") -> 4 | P22: =COUNTIF(E22:N22,"X/2")/2 -> 0 | Q22: =SUM(O22:P22) -> 4 | R22: 370000 | S22: =Q22*R22 -> 1480000
A23: 20 | B23: Đinh Văn Thống | D23: Phụ | O23: =COUNTIF(E23:N23,"X") -> 0 | P23: =COUNTIF(E23:N23,"X/2")/2 -> 0 | Q23: =SUM(O23:P23) -> 0 | R23: 280000 | S23: =Q23*R23 -> 0
A24: 21 | B24: Lê Vũ Linh | D24: Thợ | E24: x | F24: x | G24: x | H24: x | I24: x/2 | J24: x | K24: x | L24: x | M24: x | N24: x | O24: =COUNTIF(E24:N24,"X") -> 9 | P24: =COUNTIF(E24:N24,"X/2")/2 -> 0.5 | Q24: =SUM(O24:P24) -> 9.5 | R24: 380000 | S24: =Q24*R24 -> 3610000
A25: 22 | B25: Nguyễn Thị Cười | D25: Thợ | J25: x | K25: x | L25: x | M25: x | N25: x | O25: =COUNTIF(E25:N25,"X") -> 5 | P25: =COUNTIF(E25:N25,"X/2")/2 -> 0 | Q25: =SUM(O25:P25) -> 5 | R25: 280000 | S25: =Q25*R25 -> 1400000
A26: 23 | B26: Huỳnh Thanh Xuân | D26: Phụ | O26: =COUNTIF(E26:N26,"X") -> 0 | P26: =COUNTIF(E26:N26,"X/2")/2 -> 0 | Q26: =SUM(O26:P26) -> 0 | R26: 270000 | S26: =Q26*R26 -> 0
A27: 24 | B27: Lâm Hữu Phước | D27: Phụ | F27: x | G27: x | H27: x | J27: x | K27: x | L27: x | M27: x | N27: x | O27: =COUNTIF(E27:N27,"X") -> 8 | P27: =COUNTIF(E27:N27,"X/2")/2 -> 0 | Q27: =SUM(O27:P27) -> 8 | R27: 280000 | S27: =Q27*R27 -> 2240000
A28: 25 | B28: Nguyễn Văn Phao | D28: Thợ | O28: =COUNTIF(E28:N28,"X") -> 0 | P28: =COUNTIF(E28:N28,"X/2")/2 -> 0 | Q28: =SUM(O28:P28) -> 0 | R28: 370000 | S28: =Q28*R28 -> 0
A29: 26 | B29: Nguyễn Văn Đa | D29: Phụ | O29: =COUNTIF(E29:N29,"X") -> 0 | P29: =COUNTIF(E29:N29,"X/2")/2 -> 0 | Q29: =SUM(O29:P29) -> 0 | R29: 260000 | S29: =Q29*R29 -> 0
A30: 27 | B30: Lâm Kỳ Phi | D30: Thợ | F30: x | G30: x | H30: x | I30: x/2 | J30: x | K30: x | L30: x | M30: x | N30: x | O30: =COUNTIF(E30:N30,"X") -> 8 | P30: =COUNTIF(E30:N30,"X/2")/2 -> 0.5 | Q30: =SUM(O30:P30) -> 8.5 | R30: 380000 | S30: =Q30*R30 -> 3230000
A31: 28 | B31: Trần Thanh Phong | D31: Thợ | E31: x | F31: x | G31: x | H31: x | J31: x | K31: x | L31: x | M31: x | O31: =COUNTIF(E31:N31,"X") -> 8 | P31: =COUNTIF(E31:N31,"X/2")/2 -> 0 | Q31: =SUM(O31:P31) -> 8 | R31: 370000 | S31: =Q31*R31 -> 2960000
A32: 29 | B32: Trịnh Văn Phước | D32: Thợ | L32: x | M32: x | N32: x | O32: =COUNTIF(E32:N32,"X") -> 3 | P32: =COUNTIF(E32:N32,"X/2")/2 -> 0 | Q32: =SUM(O32:P32) -> 3 | R32: 380000 | S32: =Q32*R32 -> 1140000
A33: 30 | B33: Nguyễn Văn Liễu | D33: Thợ | E33: x | F33: x | G33: x | H33: x | I33: x | J33: x | K33: x | L33: x | M33: x | N33: x | O33: =COUNTIF(E33:N33,"X") -> 10 | P33: =COUNTIF(E33:N33,"X/2")/2 -> 0 | Q33: =SUM(O33:P33) -> 10 | R33: 360000 | S33: =Q33*R33 -> 3600000
A34: 31 | B34: Nguyễn Quốc Thiện | D34: Phụ | E34: x | F34: x | G34: x | H34: x | I34: x | J34: x | K34: x | L34: x | M34: x | N34: x | O34: =COUNTIF(E34:N34,"X") -> 10 | P34: =COUNTIF(E34:N34,"X/2")/2 -> 0 | Q34: =SUM(O34:P34) -> 10 | R34: 280000 | S34: =Q34*R34 -> 2800000
A35: 32 | B35: Nguyễn Văn Cường | D35: Thợ | E35: x | F35: x | G35: x | H35: x | J35: x | K35: x | L35: x | M35: x | N35: x | O35: =COUNTIF(E35:N35,"X") -> 9 | P35: =COUNTIF(E35:N35,"X/2")/2 -> 0 | Q35: =SUM(O35:P35) -> 9 | R35: 370000 | S35: =Q35*R35 -> 3330000
A36: 33 | B36: Nguyễn Thu Mè | D36: Phụ | E36: x | F36: x | G36: x | H36: x | J36: x | K36: x | L36: x | M36: x | N36: x | O36: =COUNTIF(E36:N36,"X") -> 9 | P36: =COUNTIF(E36:N36,"X/2")/2 -> 0 | Q36: =SUM(O36:P36) -> 9 | R36: 270000 | S36: =Q36*R36 -> 2430000
A37: 34 | B37: Nguyễn Văn Chờ | D37: Thợ | E37: x | F37: x | G37: x | H37: x | J37: x | K37: x | L37: x | M37: x | N37: x | O37: =COUNTIF(E37:N37,"X") -> 9 | P37: =COUNTIF(E37:N37,"X/2")/2 -> 0 | Q37: =SUM(O37:P37) -> 9 | R37: 360000 | S37: =Q37*R37 -> 3240000
A38: 35 | B38: Nguyễn Văn Châu | D38: Phụ | E38: x | F38: x | G38: x | H38: x | L38: x | M38: x | N38: x | O38: =COUNTIF(E38:N38,"X") -> 7 | P38: =COUNTIF(E38:N38,"X/2")/2 -> 0 | Q38: =SUM(O38:P38) -> 7 | R38: 270000 | S38: =Q38*R38 -> 1890000
A39: 36 | B39: Lê Quốc Thịnh | D39: Phụ | O39: =COUNTIF(E39:N39,"X") -> 0 | P39: =COUNTIF(E39:N39,"X/2")/2 -> 0 | Q39: =SUM(O39:P39) -> 0 | R39: 260000 | S39: =Q39*R39 -> 0
A40: 37 | B40: Lê Văn Xết | D40: Thợ | J40: x | K40: x | L40: x | M40: x | N40: x | O40: =COUNTIF(E40:N40,"X") -> 5 | P40: =COUNTIF(E40:N40,"X/2")/2 -> 0 | Q40: =SUM(O40:P40) -> 5 | R40: 360000 | S40: =Q40*R40 -> 1800000
...

Sheet 4
A1: BẢNG LƯƠNG (từ 21-31.T3/2026)
A2: STT | B2: HỌ TÊN | C2: GHI CHÚ | D2: CV | E2: 21 | F2: =E2+1 -> 22 | G2: =F2+1 -> 23 | H2: =G2+1 -> 24 | I2: =H2+1 -> 25 | J2: =I2+1 -> 26 | K2: =J2+1 -> 27 | L2: =K2+1 -> 28 | M2: =L2+1 -> 29 | ... O2: =N2+1 -> 31 | P2: Đủ công | Q2: Nửa công | R2: TC | S2: Lương/ngày | T2: Tổng lương | U2: Ký nhận
E3: T7 | F3: T2 | G3: CN | H3: T3 | I3: T4 | J3: T5 | K3: T6 | L3: T7 | M3: CN | N3: T2 | O3: T3
A4: 1 | B4: A Lâm | C4: =SUBTOTAL(103,C5:C22) -> 15 | D4: ĐT | E4: x | F4: x | G4: x | H4: x | I4: x | J4: x | K4: x | L4: x | M4: x | N4: x | O4: x | P4: =COUNTIF(E4:O4,"X") -> 11 | Q4: =COUNTIF(E4:I4,"X/2")/2 -> 0 | R4: =SUM(P4:Q4) -> 11 | S4: 550000 | T4: =R4*S4 -> 6050000 | U4: 9000000
A5: 2 | B5: Nguyễn Tấn Tài | C5: Có CCCD gửi cty Hưng Long | D5: Thợ | G5: x | H5: x | I5: x | J5: x | K5: x | L5: x | N5: x | O5: x | P5: =COUNTIF(E5:O5,"X") -> 8 | Q5: =COUNTIF(E5:O5,"X/2")/2 -> 0 | R5: =SUM(P5:Q5) -> 8 | S5: 380000 | T5: =R5*S5 -> 3040000
A6: 3 | B6: Mai Văn Đời | C6: Có hình CCCD | D6: Thợ | E6: x | G6: x | H6: x | I6: x | J6: x | K6: x | L6: x | N6: x | O6: x | P6: =COUNTIF(E6:O6,"X") -> 9 | Q6: =COUNTIF(E6:O6,"X/2")/2 -> 0 | R6: =SUM(P6:Q6) -> 9 | S6: 370000 | T6: =R6*S6 -> 3330000
A7: =A6+1 -> 4 | B7: Nguyễn Văn Đấu | C7: Có CCCD gửi cty Hưng Long | D7: Thợ | E7: x | G7: x | H7: x | I7: x | J7: x | K7: x | L7: x | O7: x/2 | P7: =COUNTIF(E7:O7,"X") -> 7 | Q7: =COUNTIF(E7:O7,"X/2")/2 -> 0.5 | R7: =SUM(P7:Q7) -> 7.5 | S7: 370000 | T7: =R7*S7 -> 2775000
A8: =A7+1 -> 5 | B8: Huỳnh Thanh Tùng | C8: Có hình CCCD | D8: Thợ ép | E8: x | F8: x | G8: x | H8: x | I8: x | J8: x | M8: x | N8: x/2 | O8: x | P8: =COUNTIF(E8:O8,"X") -> 8 | Q8: =COUNTIF(E8:O8,"X/2")/2 -> 0.5 | R8: =SUM(P8:Q8) -> 8.5 | S8: 350000 | T8: =R8*S8 -> 2975000
A9: =A8+1 -> 6 | B9: Nguyễn Hoàng Vũ | C9: Có CCCD gửi cty Hưng Long | D9: Phụ | E9: x | G9: x | H9: x | I9: x | J9: x | K9: x | L9: x | N9: x | O9: x | P9: =COUNTIF(E9:O9,"X") -> 9 | Q9: =COUNTIF(E9:O9,"X/2")/2 -> 0 | R9: =SUM(P9:Q9) -> 9 | S9: 320000 | T9: =R9*S9 -> 2880000
A10: =A9+1 -> 7 | B10: Nguyễn Văn Phong | C10: Có hình CCCD | D10: Phụ | E10: x | G10: x | H10: x | I10: x | J10: x | K10: x | L10: x | N10: x | O10: x | P10: =COUNTIF(E10:O10,"X") -> 9 | Q10: =COUNTIF(E10:O10,"X/2")/2 -> 0 | R10: =SUM(P10:Q10) -> 9 | S10: 300000 | T10: =R10*S10 -> 2700000
A11: =A10+1 -> 8 | B11: Nguyễn Công Thức | C11: Có CCCD gửi cty Hưng Long | D11: Phụ | E11: x | F11: x | G11: x | H11: x | I11: x | J11: x | K11: x | L11: x | M11: x | N11: x | O11: x | P11: =COUNTIF(E11:O11,"X") -> 11 | Q11: =COUNTIF(E11:O11,"X/2")/2 -> 0 | R11: =SUM(P11:Q11) -> 11 | S11: 360000 | T11: =R11*S11 -> 3960000
A12: =A11+1 -> 9 | B12: Nguyễn Tấn Lợi | C12: Có hình CCCD | D12: Thợ | E12: x | F12: x | G12: x | H12: x | I12: x | J12: x | K12: x | P12: =COUNTIF(E12:O12,"X") -> 7 | Q12: =COUNTIF(E12:O12,"X/2")/2 -> 0 | R12: =SUM(P12:Q12) -> 7 | S12: 400000 | T12: =R12*S12 -> 2800000
A13: 10 | B13: Mai Văn Bảy | C13: Có hình CCCD | D13: Phụ | E13: x | G13: x | H13: x | I13: x | J13: x | P13: =COUNTIF(E13:O13,"X") -> 5 | Q13: =COUNTIF(E13:O13,"X/2")/2 -> 0 | R13: =SUM(P13:Q13) -> 5 | S13: 280000 | T13: =R13*S13 -> 1400000
A14: =A13+1 -> 11 | B14: Huỳnh Chí Linh | C14: Có hình CCCD | D14: Thợ | E14: x | F14: x | G14: x | H14: x | I14: x | J14: x | K14: x | M14: x | N14: x | P14: =COUNTIF(E14:O14,"X") -> 9 | Q14: =COUNTIF(E14:O14,"X/2")/2 -> 0 | R14: =SUM(P14:Q14) -> 9 | S14: 400000 | T14: =R14*S14 -> 3600000
A15: =A14+1 -> 12 | B15: Nguyễn Văn Yêm | D15: Thợ | E15: x | G15: x | H15: x | I15: x | J15: x | K15: x | L15: x | N15: x | O15: x | P15: =COUNTIF(E15:O15,"X") -> 9 | Q15: =COUNTIF(E15:O15,"X/2")/2 -> 0 | R15: =SUM(P15:Q15) -> 9 | S15: 390000 | T15: =R15*S15 -> 3510000
A16: =A15+1 -> 13 | B16: Nguyễn Thanh Tùng | C16: Có CCCD gửi cty Hưng Long | D16: Thợ | E16: x | G16: x | H16: x | I16: x | J16: x | K16: x | L16: x | N16: x | O16: x | P16: =COUNTIF(E16:O16,"X") -> 9 | Q16: =COUNTIF(E16:O16,"X/2")/2 -> 0 | R16: =SUM(P16:Q16) -> 9 | S16: 370000 | T16: =R16*S16 -> 3330000
A17: =A16+1 -> 14 | B17: Nguyễn Văn Mười | D17: Thợ | E17: x | F17: x | G17: x | H17: x | I17: x | J17: x | K17: x | N17: x | P17: =COUNTIF(E17:O17,"X") -> 8 | Q17: =COUNTIF(E17:O17,"X/2")/2 -> 0 | R17: =SUM(P17:Q17) -> 8 | S17: 360000 | T17: =R17*S17 -> 2880000
A18: =A17+1 -> 15 | B18: Phạm Văn Kiệt | C18: Có CCCD gửi cty Hưng Long | D18: Thợ | E18: x | F18: x | G18: x | H18: x | I18: x | J18: x | K18: x | L18: x | N18: x | O18: x | P18: =COUNTIF(E18:O18,"X") -> 10 | Q18: =COUNTIF(E18:O18,"X/2")/2 -> 0 | R18: =SUM(P18:Q18) -> 10 | S18: 380000 | T18: =R18*S18 -> 3800000
A19: =A18+1 -> 16 | B19: Trương Văn Thông | C19: Có CCCD gửi cty Hưng Long | D19: Phụ | E19: x | G19: x | H19: x | I19: x | J19: x | K19: x | L19: x | N19: x | O19: x | P19: =COUNTIF(E19:O19,"X") -> 9 | Q19: =COUNTIF(E19:O19,"X/2")/2 -> 0 | R19: =SUM(P19:Q19) -> 9 | S19: 270000 | T19: =R19*S19 -> 2430000
A20: =A19+1 -> 17 | B20: Võ Hoàng Nam | C20: Có CCCD gửi cty Hưng Long | D20: Thợ | E20: x | G20: x | H20: x | I20: x | J20: x | K20: x | L20: x | N20: x | O20: x | P20: =COUNTIF(E20:O20,"X") -> 9 | Q20: =COUNTIF(E20:O20,"X/2")/2 -> 0 | R20: =SUM(P20:Q20) -> 9 | S20: 380000 | T20: =R20*S20 -> 3420000
A21: =A20+1 -> 18 | B21: Trần Thanh Sơn | C21: Có CCCD gửi cty Hưng Long | D21: Thợ | G21: x | H21: x | I21: x | J21: x | K21: x | L21: x | P21: =COUNTIF(E21:O21,"X") -> 6 | Q21: =COUNTIF(E21:O21,"X/2")/2 -> 0 | R21: =SUM(P21:Q21) -> 6 | S21: 370000 | T21: =R21*S21 -> 2220000
A22: =A21+1 -> 19 | B22: Đinh Văn Thống | D22: Phụ | P22: =COUNTIF(E22:O22,"X") -> 0 | Q22: =COUNTIF(E22:O22,"X/2")/2 -> 0 | R22: =SUM(P22:Q22) -> 0 | S22: 280000 | T22: =R22*S22 -> 0
A23: =A22+1 -> 20 | B23: Lê Vũ Linh | D23: Thợ | E23: x | F23: x | G23: x | H23: x | I23: x | J23: x | K23: x | L23: x | M23: x | N23: x | O23: x/2 | P23: =COUNTIF(E23:O23,"X") -> 10 | Q23: =COUNTIF(E23:O23,"X/2")/2 -> 0.5 | R23: =SUM(P23:Q23) -> 10.5 | S23: 380000 | T23: =R23*S23 -> 3990000
A24: =A23+1 -> 21 | B24: Nguyễn Thị Cười | D24: Thợ | E24: x | F24: x | G24: x | H24: x | I24: x | J24: x | K24: x | L24: x | M24: x | N24: x | O24: x/2 | P24: =COUNTIF(E24:O24,"X") -> 10 | Q24: =COUNTIF(E24:O24,"X/2")/2 -> 0.5 | R24: =SUM(P24:Q24) -> 10.5 | S24: 280000 | T24: =R24*S24 -> 2940000
A25: =A24+1 -> 22 | B25: Huỳnh Thanh Xuân | D25: Phụ | P25: =COUNTIF(E25:O25,"X") -> 0 | Q25: =COUNTIF(E25:O25,"X/2")/2 -> 0 | R25: =SUM(P25:Q25) -> 0 | S25: 270000 | T25: =R25*S25 -> 0
A26: =A25+1 -> 23 | B26: Lâm Hữu Phước | D26: Phụ | E26: x | F26: x | G26: x | H26: x | L26: x | M26: x | N26: x | O26: x | P26: =COUNTIF(E26:O26,"X") -> 8 | Q26: =COUNTIF(E26:O26,"X/2")/2 -> 0 | R26: =SUM(P26:Q26) -> 8 | S26: 280000 | T26: =R26*S26 -> 2240000
A27: =A26+1 -> 24 | B27: Nguyễn Văn Phao | D27: Thợ | P27: =COUNTIF(E27:O27,"X") -> 0 | Q27: =COUNTIF(E27:O27,"X/2")/2 -> 0 | R27: =SUM(P27:Q27) -> 0 | S27: 370000 | T27: =R27*S27 -> 0
A28: 25 | B28: Lâm Kỳ Phi | D28: Thợ | E28: x | F28: x | G28: x | H28: x | I28: x | J28: x | L28: x | M28: x | N28: x | O28: x | P28: =COUNTIF(E28:O28,"X") -> 10 | Q28: =COUNTIF(E28:O28,"X/2")/2 -> 0 | R28: =SUM(P28:Q28) -> 10 | S28: 380000 | T28: =R28*S28 -> 3800000
A29: =A28+1 -> 26 | B29: Trần Thanh Phong | D29: Thợ | E29: x | G29: x | H29: x | I29: x | J29: x | K29: x | L29: x | N29: x | O29: x | P29: =COUNTIF(E29:O29,"X") -> 9 | Q29: =COUNTIF(E29:O29,"X/2")/2 -> 0 | R29: =SUM(P29:Q29) -> 9 | S29: 370000 | T29: =R29*S29 -> 3330000
A30: =A29+1 -> 27 | B30: Trịnh Văn Phước | D30: Thợ | E30: x | H30: x | I30: x | J30: x | K30: x | L30: x | M30: x | N30: x | O30: x | P30: =COUNTIF(E30:O30,"X") -> 9 | Q30: =COUNTIF(E30:O30,"X/2")/2 -> 0 | R30: =SUM(P30:Q30) -> 9 | S30: 380000 | T30: =R30*S30 -> 3420000
A31: =A30+1 -> 28 | B31: Nguyễn Văn Liễu | D31: Thợ | E31: x | F31: x | G31: x | H31: x | I31: x | J31: x | K31: x | M31: x | N31: x | O31: x | P31: =COUNTIF(E31:O31,"X") -> 10 | Q31: =COUNTIF(E31:O31,"X/2")/2 -> 0 | R31: =SUM(P31:Q31) -> 10 | S31: 360000 | T31: =R31*S31 -> 3600000
A32: =A31+1 -> 29 | B32: Nguyễn Quốc Thiện | D32: Phụ | E32: x | G32: x | H32: x | I32: x | J32: x | K32: x | M32: x | N32: x | O32: x | P32: =COUNTIF(E32:O32,"X") -> 9 | Q32: =COUNTIF(E32:O32,"X/2")/2 -> 0 | R32: =SUM(P32:Q32) -> 9 | S32: 280000 | T32: =R32*S32 -> 2520000
A33: =A32+1 -> 30 | B33: Nguyễn Văn Cường | D33: Thợ | E33: x | F33: x | G33: x | P33: =COUNTIF(E33:O33,"X") -> 3 | Q33: =COUNTIF(E33:O33,"X/2")/2 -> 0 | R33: =SUM(P33:Q33) -> 3 | S33: 370000 | T33: =R33*S33 -> 1110000
A34: =A33+1 -> 31 | B34: Nguyễn Thu Mè | D34: Phụ | E34: x | F34: x | G34: x | L34: x | M34: x | N34: x | O34: x | P34: =COUNTIF(E34:O34,"X") -> 7 | Q34: =COUNTIF(E34:O34,"X/2")/2 -> 0 | R34: =SUM(P34:Q34) -> 7 | S34: 270000 | T34: =R34*S34 -> 1890000
A35: =A34+1 -> 32 | B35: Nguyễn Văn Chờ | D35: Thợ | E35: x | H35: x | I35: x | J35: x | L35: x | N35: x | O35: x | P35: =COUNTIF(E35:O35,"X") -> 7 | Q35: =COUNTIF(E35:O35,"X/2")/2 -> 0 | R35: =SUM(P35:Q35) -> 7 | S35: 360000 | T35: =R35*S35 -> 2520000
A36: =A35+1 -> 33 | B36: Nguyễn Văn Châu | D36: Phụ | E36: x | G36: x | H36: x | I36: x | J36: x | K36: x | N36: x | O36: x | P36: =COUNTIF(E36:O36,"X") -> 8 | Q36: =COUNTIF(E36:O36,"X/2")/2 -> 0 | R36: =SUM(P36:Q36) -> 8 | S36: 270000 | T36: =R36*S36 -> 2160000
A37: =A36+1 -> 34 | B37: Lê Quốc Thịnh | D37: Phụ | P37: =COUNTIF(E37:O37,"X") -> 0 | Q37: =COUNTIF(E37:O37,"X/2")/2 -> 0 | R37: =SUM(P37:Q37) -> 0 | S37: 260000 | T37: =R37*S37 -> 0
A38: =A37+1 -> 35 | B38: Lê Văn Xết | D38: Thợ | E38: x | G38: x | H38: x | I38: x | J38: x | K38: x | M38: x | N38: x | O38: x | P38: =COUNTIF(E38:O38,"X") -> 9 | Q38: =COUNTIF(E38:O38,"X/2")/2 -> 0 | R38: =SUM(P38:Q38) -> 9 | S38: 360000 | T38: =R38*S38 -> 3240000
A39: =A38+1 -> 36 | B39: Nguyễn Văn Thiệt | D39: Thợ | P39: =COUNTIF(E39:O39,"X") -> 0 | Q39: =COUNTIF(E39:O39,"X/2")/2 -> 0 | R39: =SUM(P39:Q39) -> 0 | S39: 360000 | T39: =R39*S39 -> 0
A40: =A39+1 -> 37 | B40: Huỳnh Văn Lý | D40: Phụ | E40: x | G40: x | H40: x | I40: x | J40: x | K40: x | L40: x | N40: x | O40: x | P40: =COUNTIF(E40:O40,"X") -> 9 | Q40: =COUNTIF(E40:O40,"X/2")/2 -> 0 | R40: =SUM(P40:Q40) -> 9 | S40: 260000 | T40: =R40*S40 -> 2340000
...

Sheet 5
A1: BẢNG LƯƠNG (từ 1-10.T4/2026)
A2: STT | B2: HỌ TÊN | C2: GHI CHÚ | D2: CV | E2: 1 | F2: =E2+1 -> 2 | G2: =F2+1 -> 3 | H2: =G2+1 -> 4 | I2: =H2+1 -> 5 | J2: =I2+1 -> 6 | K2: =J2+1 -> 7 | L2: =K2+1 -> 8 | M2: =L2+1 -> 9 | N2: =M2+1 -> 10 | O2: Đủ công | P2: Nửa công | Q2: TC | R2: Lương/ngày | S2: Tổng lương | T2: Ký nhận
E3: T4 | F3: T5 | G3: T6 | H3: T7 | I3: CN | J3: T2 | K3: T3 | L3: T4 | M3: T5 | N3: T6
A4: 1 | B4: A Lâm | C4: =SUBTOTAL(103,C5:C22) -> 15 | D4: ĐT | E4: x | F4: x | G4: x | H4: x | J4: x | K4: x | L4: x | M4: x | N4: x | O4: =COUNTIF(E4:N4,"X") -> 9 | P4: =COUNTIF(E4:I4,"X/2")/2 -> 0 | Q4: =SUM(O4:P4) -> 9 | R4: 550000 | S4: =Q4*R4 -> 4950000 | T4: 5000000
A5: 2 | B5: Nguyễn Tấn Tài | C5: Có CCCD gửi cty Hưng Long | D5: Thợ | F5: x | G5: x | H5: x | J5: x | K5: x | L5: x | M5: x | N5: x | O5: =COUNTIF(E5:N5,"X") -> 8 | P5: =COUNTIF(E5:N5,"X/2")/2 -> 0 | Q5: =SUM(O5:P5) -> 8 | R5: 380000 | S5: =Q5*R5 -> 3040000
A6: 3 | B6: Mai Văn Đời | C6: Có hình CCCD | D6: Thợ | E6: x | F6: x | G6: x | H6: x | J6: x | K6: x | L6: x | M6: x | N6: x | O6: =COUNTIF(E6:N6,"X") -> 9 | P6: =COUNTIF(E6:N6,"X/2")/2 -> 0 | Q6: =SUM(O6:P6) -> 9 | R6: 370000 | S6: =Q6*R6 -> 3330000
A7: =A6+1 -> 4 | B7: Nguyễn Văn Đấu | C7: Có CCCD gửi cty Hưng Long | D7: Thợ | E7: x | F7: x | G7: x | H7: x | K7: x | L7: x | M7: x | N7: x | O7: =COUNTIF(E7:N7,"X") -> 8 | P7: =COUNTIF(E7:N7,"X/2")/2 -> 0 | Q7: =SUM(O7:P7) -> 8 | R7: 370000 | S7: =Q7*R7 -> 2960000
A8: =A7+1 -> 5 | B8: Huỳnh Thanh Tùng | C8: Có hình CCCD | D8: Thợ ép | E8: x | F8: x/2 | G8: x | K8: x | L8: x | M8: x | N8: x/2 | O8: =COUNTIF(E8:N8,"X") -> 5 | P8: =COUNTIF(E8:N8,"X/2")/2 -> 1 | Q8: =SUM(O8:P8) -> 6 | R8: 350000 | S8: =Q8*R8 -> 2100000
A9: =A8+1 -> 6 | B9: Nguyễn Hoàng Vũ | C9: Có CCCD gửi cty Hưng Long | D9: Phụ | E9: x | F9: x | G9: x | J9: x | K9: x | L9: x | M9: x | N9: x | O9: =COUNTIF(E9:N9,"X") -> 8 | P9: =COUNTIF(E9:N9,"X/2")/2 -> 0 | Q9: =SUM(O9:P9) -> 8 | R9: 320000 | S9: =Q9*R9 -> 2560000
A10: =A9+1 -> 7 | B10: Nguyễn Văn Phong | C10: Có hình CCCD | D10: Phụ | E10: x | F10: x | G10: x | H10: x | J10: x | K10: x | L10: x | M10: x | N10: x | O10: =COUNTIF(E10:N10,"X") -> 9 | P10: =COUNTIF(E10:N10,"X/2")/2 -> 0 | Q10: =SUM(O10:P10) -> 9 | R10: 300000 | S10: =Q10*R10 -> 2700000
A11: =A10+1 -> 8 | B11: Nguyễn Công Thức | C11: Có CCCD gửi cty Hưng Long | D11: Phụ | E11: x | F11: x | G11: x | H11: x | J11: x | K11: x | L11: x | M11: x | N11: x/2 | O11: =COUNTIF(E11:N11,"X") -> 8 | P11: =COUNTIF(E11:N11,"X/2")/2 -> 0.5 | Q11: =SUM(O11:P11) -> 8.5 | R11: 360000 | S11: =Q11*R11 -> 3060000
A12: =A11+1 -> 9 | B12: Nguyễn Tấn Lợi | C12: Có hình CCCD | D12: Thợ | O12: =COUNTIF(E12:N12,"X") -> 0 | P12: =COUNTIF(E12:N12,"X/2")/2 -> 0 | Q12: =SUM(O12:P12) -> 0 | R12: 400000 | S12: =Q12*R12 -> 0
A13: 10 | B13: Mai Văn Bảy | C13: Có hình CCCD | D13: Phụ | O13: =COUNTIF(E13:N13,"X") -> 0 | P13: =COUNTIF(E13:N13,"X/2")/2 -> 0 | Q13: =SUM(O13:P13) -> 0 | R13: 280000 | S13: =Q13*R13 -> 0
A14: =A13+1 -> 11 | B14: Huỳnh Chí Linh | C14: Có hình CCCD | D14: Thợ | E14: x | F14: x | G14: x | H14: x | J14: x | K14: x | L14: x | M14: x | N14: x | O14: =COUNTIF(E14:N14,"X") -> 9 | P14: =COUNTIF(E14:N14,"X/2")/2 -> 0 | Q14: =SUM(O14:P14) -> 9 | R14: 400000 | S14: =Q14*R14 -> 3600000
A15: =A14+1 -> 12 | B15: Nguyễn Văn Yêm | D15: Thợ | E15: x | F15: x | G15: x | H15: x | J15: x | K15: x | L15: x | M15: x | N15: x | O15: =COUNTIF(E15:N15,"X") -> 9 | P15: =COUNTIF(E15:N15,"X/2")/2 -> 0 | Q15: =SUM(O15:P15) -> 9 | R15: 390000 | S15: =Q15*R15 -> 3510000
A16: =A15+1 -> 13 | B16: Nguyễn Thanh Tùng | C16: Có CCCD gửi cty Hưng Long | D16: Thợ | E16: x | F16: x | G16: x | H16: x | J16: x | K16: x | L16: x | M16: x | N16: x | O16: =COUNTIF(E16:N16,"X") -> 9 | P16: =COUNTIF(E16:N16,"X/2")/2 -> 0 | Q16: =SUM(O16:P16) -> 9 | R16: 370000 | S16: =Q16*R16 -> 3330000
A17: =A16+1 -> 14 | B17: Nguyễn Văn Mười | D17: Thợ | E17: x | F17: x | J17: x | K17: x | L17: x | O17: =COUNTIF(E17:N17,"X") -> 5 | P17: =COUNTIF(E17:N17,"X/2")/2 -> 0 | Q17: =SUM(O17:P17) -> 5 | R17: 360000 | S17: =Q17*R17 -> 1800000
A18: =A17+1 -> 15 | B18: Phạm Văn Kiệt | C18: Có CCCD gửi cty Hưng Long | D18: Thợ | E18: x | F18: x | G18: x | H18: x | L18: x | M18: x | N18: x | O18: =COUNTIF(E18:N18,"X") -> 7 | P18: =COUNTIF(E18:N18,"X/2")/2 -> 0 | Q18: =SUM(O18:P18) -> 7 | R18: 380000 | S18: =Q18*R18 -> 2660000
A19: =A18+1 -> 16 | B19: Trương Văn Thông | C19: Có CCCD gửi cty Hưng Long | D19: Phụ | E19: x | F19: x | G19: x | H19: x | J19: x | K19: x | L19: x | O19: =COUNTIF(E19:N19,"X") -> 7 | P19: =COUNTIF(E19:N19,"X/2")/2 -> 0 | Q19: =SUM(O19:P19) -> 7 | R19: 270000 | S19: =Q19*R19 -> 1890000
A20: =A19+1 -> 17 | B20: Võ Hoàng Nam | C20: Có CCCD gửi cty Hưng Long | D20: Thợ | E20: x | F20: x | G20: x | L20: x | M20: x | N20: x | O20: =COUNTIF(E20:N20,"X") -> 6 | P20: =COUNTIF(E20:N20,"X/2")/2 -> 0 | Q20: =SUM(O20:P20) -> 6 | R20: 380000 | S20: =Q20*R20 -> 2280000
A21: =A20+1 -> 18 | B21: Trần Thanh Sơn | C21: Có CCCD gửi cty Hưng Long | D21: Thợ | O21: =COUNTIF(E21:N21,"X") -> 0 | P21: =COUNTIF(E21:N21,"X/2")/2 -> 0 | Q21: =SUM(O21:P21) -> 0 | R21: 370000 | S21: =Q21*R21 -> 0
A22: =A21+1 -> 19 | B22: Đinh Văn Thống | D22: Phụ | O22: =COUNTIF(E22:N22,"X") -> 0 | P22: =COUNTIF(E22:N22,"X/2")/2 -> 0 | Q22: =SUM(O22:P22) -> 0 | R22: 280000 | S22: =Q22*R22 -> 0
A23: =A22+1 -> 20 | B23: Lê Vũ Linh | D23: Thợ | E23: x | F23: x | G23: x | H23: x | J23: x | K23: x | L23: x | N23: x | O23: =COUNTIF(E23:N23,"X") -> 8 | P23: =COUNTIF(E23:N23,"X/2")/2 -> 0 | Q23: =SUM(O23:P23) -> 8 | R23: 380000 | S23: =Q23*R23 -> 3040000
A24: =A23+1 -> 21 | B24: Nguyễn Thị Cười | D24: Thợ | E24: x | F24: x | G24: x | H24: x | J24: x | K24: x | L24: x | N24: x | O24: =COUNTIF(E24:N24,"X") -> 8 | P24: =COUNTIF(E24:N24,"X/2")/2 -> 0 | Q24: =SUM(O24:P24) -> 8 | R24: 280000 | S24: =Q24*R24 -> 2240000
A25: =A24+1 -> 22 | B25: Huỳnh Thanh Xuân | D25: Phụ | O25: =COUNTIF(E25:N25,"X") -> 0 | P25: =COUNTIF(E25:N25,"X/2")/2 -> 0 | Q25: =SUM(O25:P25) -> 0 | R25: 270000 | S25: =Q25*R25 -> 0
A26: =A25+1 -> 23 | B26: Lâm Hữu Phước | D26: Phụ | E26: x | F26: x | G26: x | J26: x | K26: x | L26: x | M26: x | N26: x | O26: =COUNTIF(E26:N26,"X") -> 8 | P26: =COUNTIF(E26:N26,"X/2")/2 -> 0 | Q26: =SUM(O26:P26) -> 8 | R26: 280000 | S26: =Q26*R26 -> 2240000
A27: =A26+1 -> 24 | B27: Nguyễn Văn Phao | D27: Thợ | O27: =COUNTIF(E27:N27,"X") -> 0 | P27: =COUNTIF(E27:N27,"X/2")/2 -> 0 | Q27: =SUM(O27:P27) -> 0 | R27: 370000 | S27: =Q27*R27 -> 0
A28: 25 | B28: Lâm Kỳ Phi | D28: Thợ | E28: x | F28: x | G28: x | J28: x | K28: x | L28: x/2 | M28: x | N28: x | O28: =COUNTIF(E28:N28,"X") -> 7 | P28: =COUNTIF(E28:N28,"X/2")/2 -> 0.5 | Q28: =SUM(O28:P28) -> 7.5 | R28: 380000 | S28: =Q28*R28 -> 2850000
A29: =A28+1 -> 26 | B29: Trần Thanh Phong | D29: Thợ | F29: x | G29: x | H29: x | J29: x | K29: x | L29: x | M29: x/2 | N29: x | O29: =COUNTIF(E29:N29,"X") -> 7 | P29: =COUNTIF(E29:N29,"X/2")/2 -> 0.5 | Q29: =SUM(O29:P29) -> 7.5 | R29: 370000 | S29: =Q29*R29 -> 2775000
A30: =A29+1 -> 27 | B30: Trịnh Văn Phước | D30: Thợ | E30: x | F30: x | G30: x | H30: x | O30: =COUNTIF(E30:N30,"X") -> 4 | P30: =COUNTIF(E30:N30,"X/2")/2 -> 0 | Q30: =SUM(O30:P30) -> 4 | R30: 380000 | S30: =Q30*R30 -> 1520000
A31: =A30+1 -> 28 | B31: Nguyễn Văn Liễu | D31: Thợ | E31: x | F31: x | G31: x | H31: x | J31: x | L31: x | M31: x | N31: x | O31: =COUNTIF(E31:N31,"X") -> 8 | P31: =COUNTIF(E31:N31,"X/2")/2 -> 0 | Q31: =SUM(O31:P31) -> 8 | R31: 360000 | S31: =Q31*R31 -> 2880000
A32: =A31+1 -> 29 | B32: Nguyễn Quốc Thiện | D32: Phụ | E32: x | F32: x | G32: x | J32: x | K32: x | L32: x | M32: x | N32: x | O32: =COUNTIF(E32:N32,"X") -> 8 | P32: =COUNTIF(E32:N32,"X/2")/2 -> 0 | Q32: =SUM(O32:P32) -> 8 | R32: 280000 | S32: =Q32*R32+200000 -> 2440000
A33: =A32+1 -> 30 | B33: Nguyễn Văn Cường | D33: Thợ | F33: x | G33: x | H33: x | J33: x | O33: =COUNTIF(E33:N33,"X") -> 4 | P33: =COUNTIF(E33:N33,"X/2")/2 -> 0 | Q33: =SUM(O33:P33) -> 4 | R33: 370000 | S33: =Q33*R33 -> 1480000
A34: =A33+1 -> 31 | B34: Nguyễn Thu Mè | D34: Phụ | E34: x | F34: x | G34: x | H34: x | J34: x | O34: =COUNTIF(E34:N34,"X") -> 5 | P34: =COUNTIF(E34:N34,"X/2")/2 -> 0 | Q34: =SUM(O34:P34) -> 5 | R34: 270000 | S34: =Q34*R34 -> 1350000
A35: =A34+1 -> 32 | B35: Nguyễn Văn Chờ | D35: Thợ | E35: x | F35: x | G35: x | O35: =COUNTIF(E35:N35,"X") -> 3 | P35: =COUNTIF(E35:N35,"X/2")/2 -> 0 | Q35: =SUM(O35:P35) -> 3 | R35: 360000 | S35: =Q35*R35 -> 1080000
A36: =A35+1 -> 33 | B36: Nguyễn Văn Châu | D36: Phụ | E36: x | F36: x | G36: x | H36: x | K36: x | L36: x | M36: x | N36: x | O36: =COUNTIF(E36:N36,"X") -> 8 | P36: =COUNTIF(E36:N36,"X/2")/2 -> 0 | Q36: =SUM(O36:P36) -> 8 | R36: 270000 | S36: =Q36*R36 -> 2160000
A37: =A36+1 -> 34 | B37: Lê Quốc Thịnh | D37: Phụ | O37: =COUNTIF(E37:N37,"X") -> 0 | P37: =COUNTIF(E37:N37,"X/2")/2 -> 0 | Q37: =SUM(O37:P37) -> 0 | R37: 260000 | S37: =Q37*R37 -> 0
A38: =A37+1 -> 35 | B38: Lê Văn Xết | D38: Thợ | O38: =COUNTIF(E38:N38,"X") -> 0 | P38: =COUNTIF(E38:N38,"X/2")/2 -> 0 | Q38: =SUM(O38:P38) -> 0 | R38: 360000 | S38: =Q38*R38 -> 0
A39: =A38+1 -> 36 | B39: Nguyễn Văn Thiệt | D39: Thợ | O39: =COUNTIF(E39:N39,"X") -> 0 | P39: =COUNTIF(E39:N39,"X/2")/2 -> 0 | Q39: =SUM(O39:P39) -> 0 | R39: 360000 | S39: =Q39*R39 -> 0
A40: =A39+1 -> 37 | B40: Huỳnh Văn Lý | D40: Phụ | E40: x | F40: x | G40: x | H40: x | J40: x | K40: x | L40: x | M40: x | N40: x | O40: =COUNTIF(E40:N40,"X") -> 9 | P40: =COUNTIF(E40:N40,"X/2")/2 -> 0 | Q40: =SUM(O40:P40) -> 9 | R40: 260000 | S40: =Q40*R40 -> 2340000
...

Sheet 6
A1: BẢNG LƯƠNG (từ 11-20.T4/2026)
A2: STT | B2: HỌ TÊN | C2: GHI CHÚ | D2: CV | E2: 11 | F2: =E2+1 -> 12 | G2: =F2+1 -> 13 | H2: =G2+1 -> 14 | I2: =H2+1 -> 15 | J2: =I2+1 -> 16 | K2: =J2+1 -> 17 | L2: =K2+1 -> 18 | M2: =L2+1 -> 19 | N2: =M2+1 -> 20 | O2: Đủ công | P2: Nửa công | Q2: TC | R2: Lương/ngày | S2: Tổng lương | T2: Ký nhận
E3: T7 | F3: CN | G3: T2 | H3: T3 | I3: T4 | J3: T5 | K3: T6 | L3: T7 | M3: CN | N3: T2
A4: 1 | B4: A Lâm | C4: =SUBTOTAL(103,C5:C22) -> 15 | D4: ĐT | E4: x | F4: x/2 | G4: x | H4: x | I4: x | J4: x | K4: x | L4: x | M4: x | N4: x | O4: =COUNTIF(E4:N4,"X") -> 9 | P4: =COUNTIF(E4:I4,"X/2")/2 -> 0.5 | Q4: =SUM(O4:P4) -> 9.5 | R4: 550000 | S4: =Q4*R4 -> 5225000 | T4: 5000000 | U4: Ứng 5 triệu
A5: 2 | B5: Nguyễn Tấn Tài | C5: Có CCCD gửi cty Hưng Long | D5: Thợ | E5: x | G5: x | H5: x | I5: x | J5: x | K5: x | L5: x | O5: =COUNTIF(E5:N5,"X") -> 7 | P5: =COUNTIF(E5:N5,"X/2")/2 -> 0 | Q5: =SUM(O5:P5) -> 7 | R5: 380000 | S5: =Q5*R5 -> 2660000
A6: 3 | B6: Mai Văn Đời | C6: Có hình CCCD | D6: Thợ | E6: x | G6: x | H6: x | I6: x | J6: x | K6: x | L6: x | M6: x | N6: x | O6: =COUNTIF(E6:N6,"X") -> 9 | P6: =COUNTIF(E6:N6,"X/2")/2 -> 0 | Q6: =SUM(O6:P6) -> 9 | R6: 370000 | S6: =Q6*R6 -> 3330000
A7: =A6+1 -> 4 | B7: Nguyễn Văn Đấu | C7: Có CCCD gửi cty Hưng Long | D7: Thợ | E7: x | G7: x | H7: x | I7: x | J7: x | K7: x | L7: x/2 | O7: =COUNTIF(E7:N7,"X") -> 6 | P7: =COUNTIF(E7:N7,"X/2")/2 -> 0.5 | Q7: =SUM(O7:P7) -> 6.5 | R7: 370000 | S7: =Q7*R7 -> 2405000
A8: =A7+1 -> 5 | B8: Huỳnh Thanh Tùng | C8: Có hình CCCD | D8: Thợ ép | E8: x | H8: x | I8: x | J8: x | K8: x | L8: x | M8: x | O8: =COUNTIF(E8:N8,"X") -> 7 | P8: =COUNTIF(E8:N8,"X/2")/2 -> 0 | Q8: =SUM(O8:P8) -> 7 | R8: 350000 | S8: =Q8*R8 -> 2450000
A9: =A8+1 -> 6 | B9: Nguyễn Hoàng Vũ | C9: Có CCCD gửi cty Hưng Long | D9: Phụ | E9: x | H9: x | I9: x | J9: x | K9: x | L9: x | N9: x | O9: =COUNTIF(E9:N9,"X") -> 7 | P9: =COUNTIF(E9:N9,"X/2")/2 -> 0 | Q9: =SUM(O9:P9) -> 7 | R9: 320000 | S9: =Q9*R9 -> 2240000
A10: =A9+1 -> 7 | B10: Nguyễn Văn Phong | C10: Có hình CCCD | D10: Phụ | E10: x | G10: x | H10: x | I10: x | J10: x | K10: x | L10: x | N10: x | O10: =COUNTIF(E10:N10,"X") -> 8 | P10: =COUNTIF(E10:N10,"X/2")/2 -> 0 | Q10: =SUM(O10:P10) -> 8 | R10: 300000 | S10: =Q10*R10 -> 2400000
A11: =A10+1 -> 8 | B11: Nguyễn Công Thức | C11: Có CCCD gửi cty Hưng Long | D11: Phụ | E11: x | F11: x/2 | G11: x | H11: x | I11: x | J11: x | K11: x | L11: x | M11: x | N11: x | O11: =COUNTIF(E11:N11,"X") -> 9 | P11: =COUNTIF(E11:N11,"X/2")/2 -> 0.5 | Q11: =SUM(O11:P11) -> 9.5 | R11: 360000 | S11: =Q11*R11 -> 3420000
A12: =A11+1 -> 9 | B12: Nguyễn Tấn Lợi | C12: Có hình CCCD | D12: Thợ | O12: =COUNTIF(E12:N12,"X") -> 0 | P12: =COUNTIF(E12:N12,"X/2")/2 -> 0 | Q12: =SUM(O12:P12) -> 0 | R12: 400000 | S12: =Q12*R12 -> 0
A13: 10 | B13: Mai Văn Bảy | C13: Có hình CCCD | D13: Phụ | O13: =COUNTIF(E13:N13,"X") -> 0 | P13: =COUNTIF(E13:N13,"X/2")/2 -> 0 | Q13: =SUM(O13:P13) -> 0 | R13: 280000 | S13: =Q13*R13 -> 0
A14: =A13+1 -> 11 | B14: Huỳnh Chí Linh | C14: Có hình CCCD | D14: Thợ | E14: x | F14: x/2 | G14: x | H14: x | I14: x | J14: x | K14: x | L14: x | M14: x | N14: x | O14: =COUNTIF(E14:N14,"X") -> 9 | P14: =COUNTIF(E14:N14,"X/2")/2 -> 0.5 | Q14: =SUM(O14:P14) -> 9.5 | R14: 400000 | S14: =Q14*R14 -> 3800000
A15: =A14+1 -> 12 | B15: Nguyễn Văn Yêm | D15: Thợ | E15: x | G15: x | H15: x | I15: x | J15: x | K15: x | L15: x | M15: x | N15: x | O15: =COUNTIF(E15:N15,"X") -> 9 | P15: =COUNTIF(E15:N15,"X/2")/2 -> 0 | Q15: =SUM(O15:P15) -> 9 | R15: 390000 | S15: =Q15*R15 -> 3510000
A16: =A15+1 -> 13 | B16: Nguyễn Thanh Tùng | C16: Có CCCD gửi cty Hưng Long | D16: Thợ | E16: x | G16: x | H16: x | I16: x | J16: x | K16: x | L16: x | M16: x | N16: x | O16: =COUNTIF(E16:N16,"X") -> 9 | P16: =COUNTIF(E16:N16,"X/2")/2 -> 0 | Q16: =SUM(O16:P16) -> 9 | R16: 370000 | S16: =Q16*R16 -> 3330000
A17: =A16+1 -> 14 | B17: Nguyễn Văn Mười | D17: Thợ | O17: =COUNTIF(E17:N17,"X") -> 0 | P17: =COUNTIF(E17:N17,"X/2")/2 -> 0 | Q17: =SUM(O17:P17) -> 0 | R17: 360000 | S17: =Q17*R17 -> 0
A18: =A17+1 -> 15 | B18: Phạm Văn Kiệt | C18: Có CCCD gửi cty Hưng Long | D18: Thợ | E18: x | F18: x/2 | G18: x | H18: x | I18: x | J18: x | K18: x | L18: x | M18: x | N18: x | O18: =COUNTIF(E18:N18,"X") -> 9 | P18: =COUNTIF(E18:N18,"X/2")/2 -> 0.5 | Q18: =SUM(O18:P18) -> 9.5 | R18: 380000 | S18: =Q18*R18 -> 3610000
A19: =A18+1 -> 16 | B19: Trương Văn Thông | C19: Có CCCD gửi cty Hưng Long | D19: Phụ | E19: x | G19: x | H19: x | O19: =COUNTIF(E19:N19,"X") -> 3 | P19: =COUNTIF(E19:N19,"X/2")/2 -> 0 | Q19: =SUM(O19:P19) -> 3 | R19: 270000 | S19: =Q19*R19 -> 810000
A20: =A19+1 -> 17 | B20: Võ Hoàng Nam | C20: Có CCCD gửi cty Hưng Long | D20: Thợ | E20: x | G20: x | H20: x | I20: x | J20: x | K20: x | L20: x | N20: x | O20: =COUNTIF(E20:N20,"X") -> 8 | P20: =COUNTIF(E20:N20,"X/2")/2 -> 0 | Q20: =SUM(O20:P20) -> 8 | R20: 380000 | S20: =Q20*R20 -> 3040000
A21: =A20+1 -> 18 | B21: Trần Thanh Sơn | C21: Có CCCD gửi cty Hưng Long | D21: Thợ | J21: x | K21: x | L21: x | M21: x | N21: x | O21: =COUNTIF(E21:N21,"X") -> 5 | P21: =COUNTIF(E21:N21,"X/2")/2 -> 0 | Q21: =SUM(O21:P21) -> 5 | R21: 370000 | S21: =Q21*R21 -> 1850000
A22: =A21+1 -> 19 | B22: Đinh Văn Thống | D22: Phụ | I22: x | J22: x | K22: x | L22: x | M22: x | N22: x | O22: =COUNTIF(E22:N22,"X") -> 6 | P22: =COUNTIF(E22:N22,"X/2")/2 -> 0 | Q22: =SUM(O22:P22) -> 6 | R22: 280000 | S22: =Q22*R22 -> 1680000
A23: =A22+1 -> 20 | B23: Lê Vũ Linh | D23: Thợ | E23: x | F23: x/2 | G23: x | H23: x | I23: x | J23: x | K23: x | L23: x | M23: x | N23: x | O23: =COUNTIF(E23:N23,"X") -> 9 | P23: =COUNTIF(E23:N23,"X/2")/2 -> 0.5 | Q23: =SUM(O23:P23) -> 9.5 | R23: 380000 | S23: =Q23*R23 -> 3610000
A24: =A23+1 -> 21 | B24: Nguyễn Thị Cười | D24: Thợ | E24: x | F24: x/2 | G24: x | H24: x | I24: x | J24: x | K24: x | L24: x | M24: x | N24: x | O24: =COUNTIF(E24:N24,"X") -> 9 | P24: =COUNTIF(E24:N24,"X/2")/2 -> 0.5 | Q24: =SUM(O24:P24) -> 9.5 | R24: 280000 | S24: =Q24*R24 -> 2660000
A25: =A24+1 -> 22 | B25: Huỳnh Thanh Xuân | D25: Phụ | O25: =COUNTIF(E25:N25,"X") -> 0 | P25: =COUNTIF(E25:N25,"X/2")/2 -> 0 | Q25: =SUM(O25:P25) -> 0 | R25: 270000 | S25: =Q25*R25 -> 0
A26: =A25+1 -> 23 | B26: Lâm Hữu Phước | D26: Phụ | E26: x | G26: x | H26: x | I26: x | J26: x | K26: x | L26: x | M26: x | N26: x/2 | O26: =COUNTIF(E26:N26,"X") -> 8 | P26: =COUNTIF(E26:N26,"X/2")/2 -> 0.5 | Q26: =SUM(O26:P26) -> 8.5 | R26: 280000 | S26: =Q26*R26 -> 2380000
A27: =A26+1 -> 24 | B27: Nguyễn Văn Phao | D27: Thợ | O27: =COUNTIF(E27:N27,"X") -> 0 | P27: =COUNTIF(E27:N27,"X/2")/2 -> 0 | Q27: =SUM(O27:P27) -> 0 | R27: 370000 | S27: =Q27*R27 -> 0
A28: 25 | B28: Lâm Kỳ Phi | D28: Thợ | E28: x | H28: x | I28: x | J28: x | K28: x | L28: x | M28: x/2 | O28: =COUNTIF(E28:N28,"X") -> 6 | P28: =COUNTIF(E28:N28,"X/2")/2 -> 0.5 | Q28: =SUM(O28:P28) -> 6.5 | R28: 400000 | S28: =Q28*R28 -> 2600000 | T28: 1000000 | U28: Ứng 1 triệu
A29: =A28+1 -> 26 | B29: Trần Thanh Phong | D29: Thợ | E29: x | H29: x | I29: x | J29: x | K29: x | L29: x | O29: =COUNTIF(E29:N29,"X") -> 6 | P29: =COUNTIF(E29:N29,"X/2")/2 -> 0 | Q29: =SUM(O29:P29) -> 6 | R29: 370000 | S29: =Q29*R29 -> 2220000 | T29: 2000000 | U29: Ứng 2 triệu
A30: =A29+1 -> 27 | B30: Trịnh Văn Phước | D30: Thợ | I30: x | J30: x | K30: x | N30: x | O30: =COUNTIF(E30:N30,"X") -> 4 | P30: =COUNTIF(E30:N30,"X/2")/2 -> 0 | Q30: =SUM(O30:P30) -> 4 | R30: 380000 | S30: =Q30*R30 -> 1520000
A31: =A30+1 -> 28 | B31: Nguyễn Văn Liễu | D31: Thợ | E31: x | G31: x | H31: x | I31: x | J31: x | K31: x | L31: x | M31: x | N31: x | O31: =COUNTIF(E31:N31,"X") -> 9 | P31: =COUNTIF(E31:N31,"X/2")/2 -> 0 | Q31: =SUM(O31:P31) -> 9 | R31: 360000 | S31: =Q31*R31 -> 3240000
A32: =A31+1 -> 29 | B32: Nguyễn Quốc Thiện | D32: Phụ | O32: =COUNTIF(E32:N32,"X") -> 0 | P32: =COUNTIF(E32:N32,"X/2")/2 -> 0 | Q32: =SUM(O32:P32) -> 0 | R32: 280000 | S32: =Q32*R32 -> 0
A33: =A32+1 -> 30 | B33: Nguyễn Văn Cường | D33: Thợ | O33: =COUNTIF(E33:N33,"X") -> 0 | P33: =COUNTIF(E33:N33,"X/2")/2 -> 0 | Q33: =SUM(O33:P33) -> 0 | R33: 370000 | S33: =Q33*R33 -> 0
A34: =A33+1 -> 31 | B34: Nguyễn Thu Mè | D34: Phụ | O34: =COUNTIF(E34:N34,"X") -> 0 | P34: =COUNTIF(E34:N34,"X/2")/2 -> 0 | Q34: =SUM(O34:P34) -> 0 | R34: 270000 | S34: =Q34*R34 -> 0
A35: =A34+1 -> 32 | B35: Nguyễn Văn Chờ | D35: Thợ | O35: =COUNTIF(E35:N35,"X") -> 0 | P35: =COUNTIF(E35:N35,"X/2")/2 -> 0 | Q35: =SUM(O35:P35) -> 0 | R35: 360000 | S35: =Q35*R35 -> 0
A36: =A35+1 -> 33 | B36: Nguyễn Văn Châu | D36: Phụ | E36: x | G36: x | H36: x | I36: x | J36: x | K36: x | L36: x | O36: =COUNTIF(E36:N36,"X") -> 7 | P36: =COUNTIF(E36:N36,"X/2")/2 -> 0 | Q36: =SUM(O36:P36) -> 7 | R36: 280000 | S36: =Q36*R36+80000 -> 2040000 | U36: Đã bù lương tuần trước
A37: =A36+1 -> 34 | B37: Lê Quốc Thịnh | D37: Phụ | O37: =COUNTIF(E37:N37,"X") -> 0 | P37: =COUNTIF(E37:N37,"X/2")/2 -> 0 | Q37: =SUM(O37:P37) -> 0 | R37: 260000 | S37: =Q37*R37 -> 0
A38: =A37+1 -> 35 | B38: Lê Văn Xết | D38: Thợ | H38: x | I38: x | J38: x | K38: x | L38: x | N38: x | O38: =COUNTIF(E38:N38,"X") -> 6 | P38: =COUNTIF(E38:N38,"X/2")/2 -> 0 | Q38: =SUM(O38:P38) -> 6 | R38: 360000 | S38: =Q38*R38 -> 2160000
A39: =A38+1 -> 36 | B39: Nguyễn Văn Thiệt | D39: Thợ | O39: =COUNTIF(E39:N39,"X") -> 0 | P39: =COUNTIF(E39:N39,"X/2")/2 -> 0 | Q39: =SUM(O39:P39) -> 0 | R39: 360000 | S39: =Q39*R39 -> 0
A40: =A39+1 -> 37 | B40: Huỳnh Văn Lý | D40: Phụ | E40: x | G40: x | H40: x | I40: x | J40: x | K40: x | L40: x | O40: =COUNTIF(E40:N40,"X") -> 7 | P40: =COUNTIF(E40:N40,"X/2")/2 -> 0 | Q40: =SUM(O40:P40) -> 7 | R40: 260000 | S40: =Q40*R40 -> 1820000
...

Sheet 7
A1: BẢNG LƯƠNG (từ 21-30.T4/2026)
A2: STT | B2: HỌ TÊN | C2: GHI CHÚ | D2: CV | E2: 21 | F2: =E2+1 -> 22 | G2: =F2+1 -> 23 | H2: =G2+1 -> 24 | I2: =H2+1 -> 25 | J2: =I2+1 -> 26 | K2: =J2+1 -> 27 | L2: =K2+1 -> 28 | M2: =L2+1 -> 29 | N2: =M2+1 -> 30 | O2: Đủ công | P2: Nửa công | Q2: TC | R2: Lương/ngày | S2: Tổng lương | T2: Ký nhận
E3: T2 | F3: T4 | G3: T5 | H3: T6 | I3: T7 | J3: CN | K3: T2 | L3: T3 | M3: T4 | N3: T5
A4: 1 | B4: A Lâm | C4: =SUBTOTAL(103,C5:C22) -> 15 | D4: ĐT | E4: x | F4: x | G4: x | H4: x | I4: x | J4: x | K4: x | L4: x | M4: x | O4: =COUNTIF(E4:N4,"X") -> 9 | P4: =COUNTIF(E4:I4,"X/2")/2 -> 0 | Q4: =SUM(O4:P4) -> 9 | R4: 550000 | S4: =Q4*R4 -> 4950000 | T4: 1800000
A5: 2 | B5: Nguyễn Tấn Tài | C5: Có CCCD gửi cty Hưng Long | D5: Thợ | K5: x | L5: x | M5: x | O5: =COUNTIF(E5:N5,"X") -> 3 | P5: =COUNTIF(E5:N5,"X/2")/2 -> 0 | Q5: =SUM(O5:P5) -> 3 | R5: 380000 | S5: =Q5*R5 -> 1140000
A6: 3 | B6: Mai Văn Đời | C6: Có hình CCCD | D6: Thợ | E6: x | F6: x | G6: x | H6: x | K6: x | L6: x | M6: x | O6: =COUNTIF(E6:N6,"X") -> 7 | P6: =COUNTIF(E6:N6,"X/2")/2 -> 0 | Q6: =SUM(O6:P6) -> 7 | R6: 370000 | S6: =Q6*R6 -> 2590000
A7: =A6+1 -> 4 | B7: Nguyễn Văn Đấu | C7: Có CCCD gửi cty Hưng Long | D7: Thợ | F7: x | G7: x | H7: x | K7: x | L7: x | M7: x | O7: =COUNTIF(E7:N7,"X") -> 6 | P7: =COUNTIF(E7:N7,"X/2")/2 -> 0 | Q7: =SUM(O7:P7) -> 6 | R7: 370000 | S7: =Q7*R7 -> 2220000 | T7: 500000
A8: =A7+1 -> 5 | B8: Huỳnh Thanh Tùng | C8: Có hình CCCD | D8: Thợ ép | F8: x | G8: x | H8: x | I8: x | J8: x | K8: x | L8: x | O8: =COUNTIF(E8:N8,"X") -> 7 | P8: =COUNTIF(E8:N8,"X/2")/2 -> 0 | Q8: =SUM(O8:P8) -> 7 | R8: 350000 | S8: =Q8*R8 -> 2450000
A9: =A8+1 -> 6 | B9: Nguyễn Hoàng Vũ | C9: Có CCCD gửi cty Hưng Long | D9: Phụ | E9: x | F9: x | G9: x | H9: x | I9: x | J9: x | K9: x | L9: x | M9: x | N9: x | O9: =COUNTIF(E9:N9,"X") -> 10 | P9: =COUNTIF(E9:N9,"X/2")/2 -> 0 | Q9: =SUM(O9:P9) -> 10 | R9: 350000 | S9: =Q9*R9 -> 3500000
